Workbook

Sheet Instructions
C2: GMAT Error Log Instructions
C5: I hope that you find this Error Log to be a useful tool in your GMAT preparation.
C7: Setting up your Error Log
C9: 1. Ungroup all of the rows and columns by clicking the "2" in both the rows and columns.
C11: 2. Type in the source of your questions in cell F4. This Error Log has organized each tab to function for 1 source. If you, like most people, will use more than 1 source, just use a different tab to record your answers.
C12: I have created 5 source tabs as a default but you can create as many as excel will handle. To create a new tab - right click on a tab which you have not filled out yet and select "Move or Copy."
C13: Once you have done this check the box which says "Create a Copy" and press OK. This will create a new tab that is a replica of the tab you copied. Kind of like a copy and paste for Excel tabs.
C15: 3. Next you will set up one of the key features in this Error Log - the Question Review Highlighting tool. Firstly, the Highlighting Tool is built in to help you identify the questions you need to come back to
C16: and perhaps spend a bit more time on.
C17: It is built around a few premises. 1) You will want to review any question you got incorrect; 2) You will want to review any question you may have gotten right but were not completely comfortable in your answer choice;
C18: and 3) If you are timing yourself on each question, you will want to review any question that did not meet your goal time.
D19: a. In row 7, in columns K-O, there is the number "120" in blue under headings PS, DS, RC, CR, and SC. These numbers will be your "goal" time for each particular type of GMAT question.
D20: The default time is 120 seconds or 2 minutes per question. You may change this as you will dependent upon your individual "goal" time for each question type.
D21: b. Next you will choose to highlight any question where you used the Process of Elimination to arrive at any answer choice but still werent completely sure of your answer choice.
D22: So if you would like to highlight these types of questions type a "1" into cell F8 (the default is Yes). If you do not want to highlight these answers then type a "0" in this cell.
D23: c. Lastly you will choose to highlight any question where you guessed at random and have very little confidence in your answer choice.
D24: If you wish to highlight types of questions type "1" into cell F9 (the default is Yes). If you do not want to highlight these answers then type a "0" in this cell.
C26: Once you have set up all your inputs, you can turn the highlighting tool on and off as you see fit. I choose only to leave it on when I want to review my answers. I find it distracting while I am actually inputting my answers.
C28: Next, I will go through each column to identify what you are inputting into each.
C29: A * indentifies inputs which are absolutely necessary to make this error log as useful as intended.
C30: Input boxes are identified easily by their gray shading and blue fonts. No shading with black fonts indicate an output/calculation.
D32: Column B - Question number column. This column is meant for you to be able to type in the answer number for each question. The default is to grow each by 1 but you can over-ride this by simply typing in your own numbers.
C33: * | D33: Column C - Question type column. In this column you will select what type of question it is. You can choose among PS (Problem Solving), DS (Data Sufficiency), RC (Reading Comprehension),
D34: CR (Critical Reasoning) or SC (Sentence Correction)
D35: Column E - Input the date in which you took the question
C36: * | D36: Column F - Input the amount of time it took you to answer each question. Input in seconds (example: 2 minutes equals 120). If you do not wish to time yourself then leave this column blank.
C37: * | D37: Columns J-N - Input your answer. Type a "1" into the appropriate box for your answer selection. Make only 1 input per question. If you input more than 1 it will possibly mess up your results.
C38: * | D38: Columns Q-S - Input how you solved the question and how comfortable you are with your answer choice. "Know" equates to you being 90-100% sure you selected the right answer and you are confident in your choice.
D39: POE equates to you eliminating some wrong answer choices but are still not totally sure among your remaining answer choices. "Guess" equates to a totally random guess because you have no idea.
C40: * | D40: Column U - Input the Correct Answer. Before diving into your questions - skip to the back of the book and find all the answers - record them in this column.
C41: * | D41: Columns Z-AA - After you have found out if you got the answer "right" or "wrong", select the box which identifies why you got the answer wrong. There are 2 choices. "Concept" means that the question tested something
D42: conceptual which you did not understand. "Stupid Error" means any question where you just made a real dumb mistake but it is obvious to you once you see the "right"
D43: answer and you understand why the correct answer is correct.
D44: Column AC - Type in any notes for each question that you might have. I suggest using this especially for answers you get wrong. Type what type of question it was (i.e. Algebra, Arithmetic, Percents, etc)
D45: that way when you review your notes you also get a hint into possible topics that you should review as well.
C47: After you have set up your Error Log and answer questions
C49: Turn the highlighting tool on to see what questions you should review more closely. Red highlighting identifies any "incorrect" answer. Yellow highlighting identifies 1 or a few things - Could mean you used POE, or a
C50: Guess to arrive at a correct answer. Or it could mean that while you got the right answer it took you longer than your goal time.
C52: Next - Print out your results (Ctrl + P). There is a performance report for each source tab. If you can't print then you can still view the report in columns BO-CA.

Sheet Source_Input (1)
B2: ="GMAT Error Log"&" - "&F5 -> GMAT Error Log - Source 1
B4: Highlight Errors? (1=YES, 0=NO) | F4: 1
B5: Question Source: | F5: Source 1
B6: Highlighting conditions: | J6: Tot. | K6: PS | L6: DS | M6: RC | N6: CR | O6: SC
B7: Time (anything greater than or equal to X secs.): | J7: =IF(ISERROR(SUMPRODUCT(K7:O7,J1017:N1017)),"n/a",SUMPRODUCT(K7:O7,J1017:N1017)) -> 120 | K7: 120 | L7: 120 | M7: 120 | N7: 120 | O7: 120
B8: POE / Medium comfort (1=YES, 0=NO) | F8: 1
B9: Guess / No comfort (1=YES, 0=NO) | F9: 1
AE10: DO NOT DELETE THESE COLUMNS
B11: Question | C11: Question | G11: Cum. Avg | H11: 10Q Avg | J11: Answer Choice | Q11: Answer Selection Method / Comfort | U11: Answer Result | Z11: Why Wrong? | AE11: CONDITIONAL | AF11: GOAL | AR11: =F5&" Performance Report" -> Source 1 Performance Report
B12: Number | C12: Type | E12: Date | F12: Time (s) | G12: Time (s) | H12: Time (s) | J12: A | K12: B | L12: C | M12: D | N12: E | Q12: Know | R12: POE | S12: Guess | U12: Correct Ans. | V12: Correct | W12: Incorrect | X12: % Correct | Z12: Concept | AA12: Stupid Error | AC12: Notes (helpful to write down question topic of any incorrect answers) | AE12: FORMATING | AF12: TIME
B13: 1 | C13: DS | F13: 320 | G13: =IF(ISERROR(AVERAGE(F$13:F13)),"n/a",AVERAGE(F$13:F13)) -> 320 | H13: =G13 -> 320 | I13: - | K13: 1 | O13: =IF(J13=1,"A",IF(K13=1,"B",IF(L13=1,"C",IF(M13=1,"D",IF(N13=1,"E","n/a"))))) -> B | Q13: 1 | U13: B | V13: =IF(O13="n/a","",IF(O13=U13,1,"")) -> 1 | W13: =IF(O13="n/a","",IF(O13<>U13,1,"")) | X13: =SUM(V$13:V13)/COUNTA(B$13:B13) -> 1 | AE13: =+IF($F$4=0,0,IF(W13=1,1,IF(OR(R13*$F$8=1,S13*$F$9=1,F13>=AF13),2,0))) -> 2 | AF13: =HLOOKUP(C13,$K$6:$O$7,2,FALSE) -> 120
B14: =+B13+1 -> 2 | C14: DS | F14: 120 | G14: =IF(ISERROR(AVERAGE(F$13:F14)),"n/a",AVERAGE(F$13:F14)) -> 220 | H14: =G14 -> 220 | K14: 1 | O14: =IF(J14=1,"A",IF(K14=1,"B",IF(L14=1,"C",IF(M14=1,"D",IF(N14=1,"E","n/a"))))) -> B | R14: 1 | U14: C | V14: =IF(O14="n/a","",IF(O14=U14,1,"")) | W14: =IF(O14="n/a","",IF(O14<>U14,1,"")) -> 1 | X14: =SUM(V$13:V14)/COUNTA(B$13:B14) -> 0.5 | Z14: 1 | AE14: =+IF($F$4=0,0,IF(W14=1,1,IF(OR(R14*$F$8=1,S14*$F$9=1,F14>=AF14),2,0))) -> 1 | AF14: =HLOOKUP(C14,$K$6:$O$7,2,FALSE) -> 120 | AR14: Date of Report: | AU14: =NOW() -> 40134.633
B15: =+B14+1 -> 3 | C15: PS | F15: 70 | G15: =IF(ISERROR(AVERAGE(F$13:F15)),"n/a",AVERAGE(F$13:F15)) -> 170 | H15: =G15 -> 170 | K15: 1 | O15: =IF(J15=1,"A",IF(K15=1,"B",IF(L15=1,"C",IF(M15=1,"D",IF(N15=1,"E","n/a"))))) -> B | Q15: 1 | U15: B | V15: =IF(O15="n/a","",IF(O15=U15,1,"")) -> 1 | W15: =IF(O15="n/a","",IF(O15<>U15,1,"")) | X15: =SUM(V$13:V15)/COUNTA(B$13:B15) -> 0.66666667 | AE15: =+IF($F$4=0,0,IF(W15=1,1,IF(OR(R15*$F$8=1,S15*$F$9=1,F15>=AF15),2,0))) -> 0 | AF15: =HLOOKUP(C15,$K$6:$O$7,2,FALSE) -> 120
B16: =+B15+1 -> 4 | C16: PS | F16: 80 | G16: =IF(ISERROR(AVERAGE(F$13:F16)),"n/a",AVERAGE(F$13:F16)) -> 147.5 | H16: =G16 -> 147.5 | K16: 1 | O16: =IF(J16=1,"A",IF(K16=1,"B",IF(L16=1,"C",IF(M16=1,"D",IF(N16=1,"E","n/a"))))) -> B | R16: 1 | U16: B | V16: =IF(O16="n/a","",IF(O16=U16,1,"")) -> 1 | W16: =IF(O16="n/a","",IF(O16<>U16,1,"")) | X16: =SUM(V$13:V16)/COUNTA(B$13:B16) -> 0.75 | AE16: =+IF($F$4=0,0,IF(W16=1,1,IF(OR(R16*$F$8=1,S16*$F$9=1,F16>=AF16),2,0))) -> 2 | AF16: =HLOOKUP(C16,$K$6:$O$7,2,FALSE) -> 120
B17: =+B16+1 -> 5 | C17: CR | F17: 110 | G17: =IF(ISERROR(AVERAGE(F$13:F17)),"n/a",AVERAGE(F$13:F17)) -> 140 | H17: =G17 -> 140 | K17: 1 | O17: =IF(J17=1,"A",IF(K17=1,"B",IF(L17=1,"C",IF(M17=1,"D",IF(N17=1,"E","n/a"))))) -> B | Q17: 1 | U17: B | V17: =IF(O17="n/a","",IF(O17=U17,1,"")) -> 1 | W17: =IF(O17="n/a","",IF(O17<>U17,1,"")) | X17: =SUM(V$13:V17)/COUNTA(B$13:B17) -> 0.8 | AE17: =+IF($F$4=0,0,IF(W17=1,1,IF(OR(R17*$F$8=1,S17*$F$9=1,F17>=AF17),2,0))) -> 0 | AF17: =HLOOKUP(C17,$K$6:$O$7,2,FALSE) -> 120 | AU17: Correct | AV17: Know | AW17: POE | AX17: Guess | AY17: Incorrect | AZ17: Concept | BA17: Stpd Error | BB17: Accuracy | BC17: Timing | BD17: +/- Goal
B18: =+B17+1 -> 6 | C18: CR | F18: 95 | G18: =IF(ISERROR(AVERAGE(F$13:F18)),"n/a",AVERAGE(F$13:F18)) -> 132.5 | H18: =G18 -> 132.5 | K18: 1 | O18: =IF(J18=1,"A",IF(K18=1,"B",IF(L18=1,"C",IF(M18=1,"D",IF(N18=1,"E","n/a"))))) -> B | R18: 1 | U18: D | V18: =IF(O18="n/a","",IF(O18=U18,1,"")) | W18: =IF(O18="n/a","",IF(O18<>U18,1,"")) -> 1 | X18: =SUM(V$13:V18)/COUNTA(B$13:B18) -> 0.66666667 | AA18: 1 | AE18: =+IF($F$4=0,0,IF(W18=1,1,IF(OR(R18*$F$8=1,S18*$F$9=1,F18>=AF18),2,0))) -> 1 | AF18: =HLOOKUP(C18,$K$6:$O$7,2,FALSE) -> 120 | AR18: All Questions | AU18: =V1015 -> 7 | AV18: =Q1015 -> 5 | AW18: =R1015 -> 5 | AX18: =S1015 -> 0 | AY18: =W1015 -> 3 | AZ18: =Z1015 -> 1 | BA18: =AA1015 -> 2 | BB18: =IF(ISERROR(AU18/(AU18+AY18)),"n/a",AU18/(AU18+AY18)) -> 0.7 | BC18: =IF(ISERROR(TEXT($E$1023,"00")&":"&TEXT($F$1023,"00")),"n/a",TEXT($E$1023,"00")&":"&TEXT($F$1023,"00")) -> 01:57 | BD18: =IF(ISERROR(BF18&TEXT($E$1040,"00")&":"&TEXT($F$1040,"00")),"n/a",BF18&TEXT($E$1040,"00")&":"&TEXT($F$1040,"00")) -> -00:03 | BF18: =IF(F1032<0,"-","+") -> -
B19: =+B18+1 -> 7 | C19: RC | F19: 130 | G19: =IF(ISERROR(AVERAGE(F$13:F19)),"n/a",AVERAGE(F$13:F19)) -> 132.14286 | H19: =G19 -> 132.14286 | K19: 1 | O19: =IF(J19=1,"A",IF(K19=1,"B",IF(L19=1,"C",IF(M19=1,"D",IF(N19=1,"E","n/a"))))) -> B | Q19: 1 | U19: B | V19: =IF(O19="n/a","",IF(O19=U19,1,"")) -> 1 | W19: =IF(O19="n/a","",IF(O19<>U19,1,"")) | X19: =SUM(V$13:V19)/COUNTA(B$13:B19) -> 0.71428571 | AE19: =+IF($F$4=0,0,IF(W19=1,1,IF(OR(R19*$F$8=1,S19*$F$9=1,F19>=AF19),2,0))) -> 2 | AF19: =HLOOKUP(C19,$K$6:$O$7,2,FALSE) -> 120 | AV19: =+IF(ISERROR(AV18/SUM($AU$18,$AY$18)),"n/a",AV18/SUM($AU$18,$AY$18)) -> 0.5 | AW19: =+IF(ISERROR(AW18/SUM($AU$18,$AY$18)),"n/a",AW18/SUM($AU$18,$AY$18)) -> 0.5 | AX19: =+IF(ISERROR(AX18/SUM($AU$18,$AY$18)),"n/a",AX18/SUM($AU$18,$AY$18)) -> 0 | AZ19: =+IF(ISERROR(AZ18/$AY$18),"n/a",AZ18/$AY$18) -> 0.33333333 | BA19: =+IF(ISERROR(BA18/$AY$18),"n/a",BA18/$AY$18) -> 0.66666667
B20: =+B19+1 -> 8 | C20: RC | F20: 100 | G20: =IF(ISERROR(AVERAGE(F$13:F20)),"n/a",AVERAGE(F$13:F20)) -> 128.125 | H20: =G20 -> 128.125 | K20: 1 | O20: =IF(J20=1,"A",IF(K20=1,"B",IF(L20=1,"C",IF(M20=1,"D",IF(N20=1,"E","n/a"))))) -> B | R20: 1 | U20: B | V20: =IF(O20="n/a","",IF(O20=U20,1,"")) -> 1 | W20: =IF(O20="n/a","",IF(O20<>U20,1,"")) | X20: =SUM(V$13:V20)/COUNTA(B$13:B20) -> 0.75 | AE20: =+IF($F$4=0,0,IF(W20=1,1,IF(OR(R20*$F$8=1,S20*$F$9=1,F20>=AF20),2,0))) -> 2 | AF20: =HLOOKUP(C20,$K$6:$O$7,2,FALSE) -> 120 | AR20: Performance by Question Type
B21: =+B20+1 -> 9 | C21: SC | F21: 65 | G21: =IF(ISERROR(AVERAGE(F$13:F21)),"n/a",AVERAGE(F$13:F21)) -> 121.11111 | H21: =G21 -> 121.11111 | K21: 1 | O21: =IF(J21=1,"A",IF(K21=1,"B",IF(L21=1,"C",IF(M21=1,"D",IF(N21=1,"E","n/a"))))) -> B | R21: 1 | U21: A | V21: =IF(O21="n/a","",IF(O21=U21,1,"")) | W21: =IF(O21="n/a","",IF(O21<>U21,1,"")) -> 1 | X21: =SUM(V$13:V21)/COUNTA(B$13:B21) -> 0.66666667 | AA21: 1 | AE21: =+IF($F$4=0,0,IF(W21=1,1,IF(OR(R21*$F$8=1,S21*$F$9=1,F21>=AF21),2,0))) -> 1 | AF21: =HLOOKUP(C21,$K$6:$O$7,2,FALSE) -> 120
B22: =+B21+1 -> 10 | C22: SC | F22: 80 | G22: =IF(ISERROR(AVERAGE(F$13:F22)),"n/a",AVERAGE(F$13:F22)) -> 117 | H22: =G22 -> 117 | K22: 1 | O22: =IF(J22=1,"A",IF(K22=1,"B",IF(L22=1,"C",IF(M22=1,"D",IF(N22=1,"E","n/a"))))) -> B | Q22: 1 | U22: B | V22: =IF(O22="n/a","",IF(O22=U22,1,"")) -> 1 | W22: =IF(O22="n/a","",IF(O22<>U22,1,"")) | X22: =SUM(V$13:V22)/COUNTA(B$13:B22) -> 0.7 | AE22: =+IF($F$4=0,0,IF(W22=1,1,IF(OR(R22*$F$8=1,S22*$F$9=1,F22>=AF22),2,0))) -> 0 | AF22: =HLOOKUP(C22,$K$6:$O$7,2,FALSE) -> 120 | AR22: Problem Solving | AU22: =V1017 -> 2 | AV22: =Q1017 -> 1 | AW22: =R1017 -> 1 | AX22: =S1017 -> 0 | AY22: =$W$1017 -> 0 | AZ22: =Z1017 -> 0 | BA22: =AA1017 -> 0 | BB22: =IF(ISERROR(AU22/(AU22+AY22)),"n/a",AU22/(AU22+AY22)) -> 1 | BC22: =IF(ISERROR(TEXT($E$1025,"00")&":"&TEXT($F$1025,"00")),"n/a",TEXT($E$1025,"00")&":"&TEXT($F$1025,"00")) -> 01:15 | BD22: =IF(ISERROR(BF22&TEXT($E$1042,"00")&":"&TEXT($F$1042,"00")),"n/a",BF22&TEXT($E$1042,"00")&":"&TEXT($F$1042,"00")) -> -00:45 | BF22: =IF(F1034<0,"-","+") -> -
B23: =+B22+1 -> 11 | G23: =IF(ISERROR(AVERAGE(F$13:F23)),"n/a",AVERAGE(F$13:F23)) -> 117 | H23: =G23 -> 117 | O23: =IF(J23=1,"A",IF(K23=1,"B",IF(L23=1,"C",IF(M23=1,"D",IF(N23=1,"E","n/a"))))) -> n/a | V23: =IF(O23="n/a","",IF(O23=U23,1,"")) | W23: =IF(O23="n/a","",IF(O23<>U23,1,"")) | X23: =SUM(V$13:V23)/COUNTA(B$13:B23) -> 0.63636364 | AE23: =+IF($F$4=0,0,IF(W23=1,1,IF(OR(R23*$F$8=1,S23*$F$9=1,F23>=AF23),2,0))) -> #N/A | AF23: =HLOOKUP(C23,$K$6:$O$7,2,FALSE) -> #N/A | AV23: =+IF(ISERROR(AV22/SUM($AU$22,$AY$22)),"n/a",AV22/SUM($AU$22,$AY$22)) -> 0.5 | AW23: =+IF(ISERROR(AW22/SUM($AU$22,$AY$22)),"n/a",AW22/SUM($AU$22,$AY$22)) -> 0.5 | AX23: =+IF(ISERROR(AX22/SUM($AU$22,$AY$22)),"n/a",AX22/SUM($AU$22,$AY$22)) -> 0 | AZ23: =+IF(ISERROR(AZ22/$AY$22),"n/a",AZ22/$AY$22) -> n/a | BA23: =+IF(ISERROR(BA22/$AY$22),"n/a",BA22/$AY$22) -> n/a
B24: =+B23+1 -> 12 | G24: =IF(ISERROR(AVERAGE(F$13:F24)),"n/a",AVERAGE(F$13:F24)) -> 117 | H24: =G24 -> 117 | O24: =IF(J24=1,"A",IF(K24=1,"B",IF(L24=1,"C",IF(M24=1,"D",IF(N24=1,"E","n/a"))))) -> n/a | V24: =IF(O24="n/a","",IF(O24=U24,1,"")) | W24: =IF(O24="n/a","",IF(O24<>U24,1,"")) | X24: =SUM(V$13:V24)/COUNTA(B$13:B24) -> 0.58333333 | AE24: =+IF($F$4=0,0,IF(W24=1,1,IF(OR(R24*$F$8=1,S24*$F$9=1,F24>=AF24),2,0))) -> #N/A | AF24: =HLOOKUP(C24,$K$6:$O$7,2,FALSE) -> #N/A
B25: =+B24+1 -> 13 | G25: =IF(ISERROR(AVERAGE(F$13:F25)),"n/a",AVERAGE(F$13:F25)) -> 117 | H25: =G25 -> 117 | O25: =IF(J25=1,"A",IF(K25=1,"B",IF(L25=1,"C",IF(M25=1,"D",IF(N25=1,"E","n/a"))))) -> n/a | V25: =IF(O25="n/a","",IF(O25=U25,1,"")) | W25: =IF(O25="n/a","",IF(O25<>U25,1,"")) | X25: =SUM(V$13:V25)/COUNTA(B$13:B25) -> 0.53846154 | AE25: =+IF($F$4=0,0,IF(W25=1,1,IF(OR(R25*$F$8=1,S25*$F$9=1,F25>=AF25),2,0))) -> #N/A | AF25: =HLOOKUP(C25,$K$6:$O$7,2,FALSE) -> #N/A | AR25: Data Sufficiency | AU25: =$V$1018 -> 1 | AV25: =Q1018 -> 1 | AW25: =R1018 -> 1 | AX25: =S1018 -> 0 | AY25: =$W$1018 -> 1 | AZ25: =Z1018 -> 1 | BA25: =AA1018 -> 0 | BB25: =IF(ISERROR(AU25/(AU25+AY25)),"n/a",AU25/(AU25+AY25)) -> 0.5 | BC25: =IF(ISERROR(TEXT($E$1026,"00")&":"&TEXT($F$1026,"00")),"n/a",TEXT($E$1026,"00")&":"&TEXT($F$1026,"00")) -> 03:40 | BD25: =IF(ISERROR(BF25&TEXT($E$1043,"00")&":"&TEXT($F$1043,"00")),"n/a",BF25&TEXT($E$1043,"00")&":"&TEXT($F$1043,"00")) -> +01:40 | BF25: =IF(F1035<0,"-","+") -> +
B26: =+B25+1 -> 14 | G26: =IF(ISERROR(AVERAGE(F$13:F26)),"n/a",AVERAGE(F$13:F26)) -> 117 | H26: =G26 -> 117 | O26: =IF(J26=1,"A",IF(K26=1,"B",IF(L26=1,"C",IF(M26=1,"D",IF(N26=1,"E","n/a"))))) -> n/a | V26: =IF(O26="n/a","",IF(O26=U26,1,"")) | W26: =IF(O26="n/a","",IF(O26<>U26,1,"")) | X26: =SUM(V$13:V26)/COUNTA(B$13:B26) -> 0.5 | AE26: =+IF($F$4=0,0,IF(W26=1,1,IF(OR(R26*$F$8=1,S26*$F$9=1,F26>=AF26),2,0))) -> #N/A | AF26: =HLOOKUP(C26,$K$6:$O$7,2,FALSE) -> #N/A | AV26: =+IF(ISERROR(AV25/SUM($AU$25,$AY$25)),"n/a",AV25/SUM($AU$25,$AY$25)) -> 0.5 | AW26: =+IF(ISERROR(AW25/SUM($AU$25,$AY$25)),"n/a",AW25/SUM($AU$25,$AY$25)) -> 0.5 | AX26: =+IF(ISERROR(AX25/SUM($AU$25,$AY$25)),"n/a",AX25/SUM($AU$25,$AY$25)) -> 0 | AZ26: =+IF(ISERROR(AZ25/$AY$25),"n/a",AZ25/$AY$25) -> 1 | BA26: =+IF(ISERROR(BA25/$AY$25),"n/a",BA25/$AY$25) -> 0
B27: =+B26+1 -> 15 | G27: =IF(ISERROR(AVERAGE(F$13:F27)),"n/a",AVERAGE(F$13:F27)) -> 117 | H27: =G27 -> 117 | O27: =IF(J27=1,"A",IF(K27=1,"B",IF(L27=1,"C",IF(M27=1,"D",IF(N27=1,"E","n/a"))))) -> n/a | V27: =IF(O27="n/a","",IF(O27=U27,1,"")) | W27: =IF(O27="n/a","",IF(O27<>U27,1,"")) | X27: =SUM(V$13:V27)/COUNTA(B$13:B27) -> 0.46666667 | AE27: =+IF($F$4=0,0,IF(W27=1,1,IF(OR(R27*$F$8=1,S27*$F$9=1,F27>=AF27),2,0))) -> #N/A | AF27: =HLOOKUP(C27,$K$6:$O$7,2,FALSE) -> #N/A
B28: =+B27+1 -> 16 | G28: =IF(ISERROR(AVERAGE(F$13:F28)),"n/a",AVERAGE(F$13:F28)) -> 117 | H28: =G28 -> 117 | O28: =IF(J28=1,"A",IF(K28=1,"B",IF(L28=1,"C",IF(M28=1,"D",IF(N28=1,"E","n/a"))))) -> n/a | V28: =IF(O28="n/a","",IF(O28=U28,1,"")) | W28: =IF(O28="n/a","",IF(O28<>U28,1,"")) | X28: =SUM(V$13:V28)/COUNTA(B$13:B28) -> 0.4375 | AE28: =+IF($F$4=0,0,IF(W28=1,1,IF(OR(R28*$F$8=1,S28*$F$9=1,F28>=AF28),2,0))) -> #N/A | AF28: =HLOOKUP(C28,$K$6:$O$7,2,FALSE) -> #N/A | AR28: Reading Comprehension | AU28: =$V$1019 -> 2 | AV28: =Q1019 -> 1 | AW28: =R1019 -> 1 | AX28: =S1019 -> 0 | AY28: =$W$1019 -> 0 | AZ28: =Z1019 -> 0 | BA28: =AA1019 -> 0 | BB28: =IF(ISERROR(AU28/(AU28+AY28)),"n/a",AU28/(AU28+AY28)) -> 1 | BC28: =IF(ISERROR(TEXT($E$1027,"00")&":"&TEXT($F$1027,"00")),"n/a",TEXT($E$1027,"00")&":"&TEXT($F$1027,"00")) -> 01:55 | BD28: =IF(ISERROR(BF28&TEXT($E$1044,"00")&":"&TEXT($F$1044,"00")),"n/a",BF28&TEXT($E$1044,"00")&":"&TEXT($F$1044,"00")) -> -00:05 | BF28: =IF(F1036<0,"-","+") -> -
B29: =+B28+1 -> 17 | G29: =IF(ISERROR(AVERAGE(F$13:F29)),"n/a",AVERAGE(F$13:F29)) -> 117 | H29: =G29 -> 117 | O29: =IF(J29=1,"A",IF(K29=1,"B",IF(L29=1,"C",IF(M29=1,"D",IF(N29=1,"E","n/a"))))) -> n/a | V29: =IF(O29="n/a","",IF(O29=U29,1,"")) | W29: =IF(O29="n/a","",IF(O29<>U29,1,"")) | X29: =SUM(V$13:V29)/COUNTA(B$13:B29) -> 0.41176471 | AE29: =+IF($F$4=0,0,IF(W29=1,1,IF(OR(R29*$F$8=1,S29*$F$9=1,F29>=AF29),2,0))) -> #N/A | AF29: =HLOOKUP(C29,$K$6:$O$7,2,FALSE) -> #N/A | AV29: =+IF(ISERROR(AV28/SUM($AU$28,$AY$28)),"n/a",AV28/SUM($AU$28,$AY$28)) -> 0.5 | AW29: =+IF(ISERROR(AW28/SUM($AU$28,$AY$28)),"n/a",AW28/SUM($AU$28,$AY$28)) -> 0.5 | AX29: =+IF(ISERROR(AX28/SUM($AU$28,$AY$28)),"n/a",AX28/SUM($AU$28,$AY$28)) -> 0 | AZ29: =+IF(ISERROR(AZ28/$AY$28),"n/a",AZ28/$AY$28) -> n/a | BA29: =+IF(ISERROR(BA28/$AY$28),"n/a",BA28/$AY$28) -> n/a
B30: =+B29+1 -> 18 | G30: =IF(ISERROR(AVERAGE(F$13:F30)),"n/a",AVERAGE(F$13:F30)) -> 117 | H30: =G30 -> 117 | O30: =IF(J30=1,"A",IF(K30=1,"B",IF(L30=1,"C",IF(M30=1,"D",IF(N30=1,"E","n/a"))))) -> n/a | V30: =IF(O30="n/a","",IF(O30=U30,1,"")) | W30: =IF(O30="n/a","",IF(O30<>U30,1,"")) | X30: =SUM(V$13:V30)/COUNTA(B$13:B30) -> 0.38888889 | AE30: =+IF($F$4=0,0,IF(W30=1,1,IF(OR(R30*$F$8=1,S30*$F$9=1,F30>=AF30),2,0))) -> #N/A | AF30: =HLOOKUP(C30,$K$6:$O$7,2,FALSE) -> #N/A
B31: =+B30+1 -> 19 | G31: =IF(ISERROR(AVERAGE(F$13:F31)),"n/a",AVERAGE(F$13:F31)) -> 117 | H31: =G31 -> 117 | O31: =IF(J31=1,"A",IF(K31=1,"B",IF(L31=1,"C",IF(M31=1,"D",IF(N31=1,"E","n/a"))))) -> n/a | V31: =IF(O31="n/a","",IF(O31=U31,1,"")) | W31: =IF(O31="n/a","",IF(O31<>U31,1,"")) | X31: =SUM(V$13:V31)/COUNTA(B$13:B31) -> 0.36842105 | AE31: =+IF($F$4=0,0,IF(W31=1,1,IF(OR(R31*$F$8=1,S31*$F$9=1,F31>=AF31),2,0))) -> #N/A | AF31: =HLOOKUP(C31,$K$6:$O$7,2,FALSE) -> #N/A | AR31: Critical Reasoning | AU31: =$V$1020 -> 1 | AV31: =Q1020 -> 1 | AW31: =R1020 -> 1 | AX31: =S1020 -> 0 | AY31: =$W$1020 -> 1 | AZ31: =Z1020 -> 0 | BA31: =AA1020 -> 1 | BB31: =IF(ISERROR(AU31/(AU31+AY31)),"n/a",AU31/(AU31+AY31)) -> 0.5 | BC31: =IF(ISERROR(TEXT($E$1028,"00")&":"&TEXT($F$1028,"00")),"n/a",TEXT($E$1028,"00")&":"&TEXT($F$1028,"00")) -> 01:43 | BD31: =IF(ISERROR(BF31&TEXT($E$1045,"00")&":"&TEXT($F$1045,"00")),"n/a",BF31&TEXT($E$1045,"00")&":"&TEXT($F$1045,"00")) -> -00:18 | BF31: =IF(F1037<0,"-","+") -> -
B32: =+B31+1 -> 20 | G32: =IF(ISERROR(AVERAGE(F$13:F32)),"n/a",AVERAGE(F$13:F32)) -> 117 | H32: =G32 -> 117 | O32: =IF(J32=1,"A",IF(K32=1,"B",IF(L32=1,"C",IF(M32=1,"D",IF(N32=1,"E","n/a"))))) -> n/a | V32: =IF(O32="n/a","",IF(O32=U32,1,"")) | W32: =IF(O32="n/a","",IF(O32<>U32,1,"")) | X32: =SUM(V$13:V32)/COUNTA(B$13:B32) -> 0.35 | AE32: =+IF($F$4=0,0,IF(W32=1,1,IF(OR(R32*$F$8=1,S32*$F$9=1,F32>=AF32),2,0))) -> #N/A | AF32: =HLOOKUP(C32,$K$6:$O$7,2,FALSE) -> #N/A | AV32: =+IF(ISERROR(AV31/SUM($AU$31,$AY$31)),"n/a",AV31/SUM($AU$31,$AY$31)) -> 0.5 | AW32: =+IF(ISERROR(AW31/SUM($AU$31,$AY$31)),"n/a",AW31/SUM($AU$31,$AY$31)) -> 0.5 | AX32: =+IF(ISERROR(AX31/SUM($AU$31,$AY$31)),"n/a",AX31/SUM($AU$31,$AY$31)) -> 0 | AZ32: =+IF(ISERROR(AZ31/$AY$31),"n/a",AZ31/$AY$31) -> 0 | BA32: =+IF(ISERROR(BA31/$AY$31),"n/a",BA31/$AY$31) -> 1
B33: =+B32+1 -> 21 | G33: =IF(ISERROR(AVERAGE(F$13:F33)),"n/a",AVERAGE(F$13:F33)) -> 117 | H33: =G33 -> 117 | O33: =IF(J33=1,"A",IF(K33=1,"B",IF(L33=1,"C",IF(M33=1,"D",IF(N33=1,"E","n/a"))))) -> n/a | V33: =IF(O33="n/a","",IF(O33=U33,1,"")) | W33: =IF(O33="n/a","",IF(O33<>U33,1,"")) | X33: =SUM(V$13:V33)/COUNTA(B$13:B33) -> 0.33333333 | AE33: =+IF($F$4=0,0,IF(W33=1,1,IF(OR(R33*$F$8=1,S33*$F$9=1,F33>=AF33),2,0))) -> #N/A | AF33: =HLOOKUP(C33,$K$6:$O$7,2,FALSE) -> #N/A
B34: =+B33+1 -> 22 | G34: =IF(ISERROR(AVERAGE(F$13:F34)),"n/a",AVERAGE(F$13:F34)) -> 117 | H34: =G34 -> 117 | O34: =IF(J34=1,"A",IF(K34=1,"B",IF(L34=1,"C",IF(M34=1,"D",IF(N34=1,"E","n/a"))))) -> n/a | V34: =IF(O34="n/a","",IF(O34=U34,1,"")) | W34: =IF(O34="n/a","",IF(O34<>U34,1,"")) | X34: =SUM(V$13:V34)/COUNTA(B$13:B34) -> 0.31818182 | AE34: =+IF($F$4=0,0,IF(W34=1,1,IF(OR(R34*$F$8=1,S34*$F$9=1,F34>=AF34),2,0))) -> #N/A | AF34: =HLOOKUP(C34,$K$6:$O$7,2,FALSE) -> #N/A | AR34: Sentence Correction | AU34: =$V$1021 -> 1 | AV34: =Q1021 -> 1 | AW34: =R1021 -> 1 | AX34: =S1021 -> 0 | AY34: =$W$1021 -> 1 | AZ34: =Z1021 -> 0 | BA34: =AA1021 -> 1 | BB34: =IF(ISERROR(AU34/(AU34+AY34)),"n/a",AU34/(AU34+AY34)) -> 0.5 | BC34: =IF(ISERROR(TEXT($E$1029,"00")&":"&TEXT($F$1029,"00")),"n/a",TEXT($E$1029,"00")&":"&TEXT($F$1029,"00")) -> 01:13 | BD34: =IF(ISERROR(BF34&TEXT($E$1046,"00")&":"&TEXT($F$1046,"00")),"n/a",BF34&TEXT($E$1046,"00")&":"&TEXT($F$1046,"00")) -> -00:48 | BF34: =IF(F1038<0,"-","+") -> -
B35: =+B34+1 -> 23 | G35: =IF(ISERROR(AVERAGE(F$13:F35)),"n/a",AVERAGE(F$13:F35)) -> 117 | H35: =G35 -> 117 | O35: =IF(J35=1,"A",IF(K35=1,"B",IF(L35=1,"C",IF(M35=1,"D",IF(N35=1,"E","n/a"))))) -> n/a | V35: =IF(O35="n/a","",IF(O35=U35,1,"")) | W35: =IF(O35="n/a","",IF(O35<>U35,1,"")) | X35: =SUM(V$13:V35)/COUNTA(B$13:B35) -> 0.30434783 | AE35: =+IF($F$4=0,0,IF(W35=1,1,IF(OR(R35*$F$8=1,S35*$F$9=1,F35>=AF35),2,0))) -> #N/A | AF35: =HLOOKUP(C35,$K$6:$O$7,2,FALSE) -> #N/A | AV35: =+IF(ISERROR(AV34/SUM($AU$34,$AY$34)),"n/a",AV34/SUM($AU$34,$AY$34)) -> 0.5 | AW35: =+IF(ISERROR(AW34/SUM($AU$34,$AY$34)),"n/a",AW34/SUM($AU$34,$AY$34)) -> 0.5 | AX35: =+IF(ISERROR(AX34/SUM($AU$34,$AY$34)),"n/a",AX34/SUM($AU$34,$AY$34)) -> 0 | AZ35: =+IF(ISERROR(AZ34/$AY$34),"n/a",AZ34/$AY$34) -> 0 | BA35: =+IF(ISERROR(BA34/$AY$34),"n/a",BA34/$AY$34) -> 1
B36: =+B35+1 -> 24 | G36: =IF(ISERROR(AVERAGE(F$13:F36)),"n/a",AVERAGE(F$13:F36)) -> 117 | H36: =G36 -> 117 | O36: =IF(J36=1,"A",IF(K36=1,"B",IF(L36=1,"C",IF(M36=1,"D",IF(N36=1,"E","n/a"))))) -> n/a | V36: =IF(O36="n/a","",IF(O36=U36,1,"")) | W36: =IF(O36="n/a","",IF(O36<>U36,1,"")) | X36: =SUM(V$13:V36)/COUNTA(B$13:B36) -> 0.29166667 | AE36: =+IF($F$4=0,0,IF(W36=1,1,IF(OR(R36*$F$8=1,S36*$F$9=1,F36>=AF36),2,0))) -> #N/A | AF36: =HLOOKUP(C36,$K$6:$O$7,2,FALSE) -> #N/A | BF36: =BB18 -> 0.7 | BG36: Total
B37: =+B36+1 -> 25 | G37: =IF(ISERROR(AVERAGE(F$13:F37)),"n/a",AVERAGE(F$13:F37)) -> 117 | H37: =G37 -> 117 | O37: =IF(J37=1,"A",IF(K37=1,"B",IF(L37=1,"C",IF(M37=1,"D",IF(N37=1,"E","n/a"))))) -> n/a | V37: =IF(O37="n/a","",IF(O37=U37,1,"")) | W37: =IF(O37="n/a","",IF(O37<>U37,1,"")) | X37: =SUM(V$13:V37)/COUNTA(B$13:B37) -> 0.28 | AE37: =+IF($F$4=0,0,IF(W37=1,1,IF(OR(R37*$F$8=1,S37*$F$9=1,F37>=AF37),2,0))) -> #N/A | AF37: =HLOOKUP(C37,$K$6:$O$7,2,FALSE) -> #N/A | BF37: =BB22 -> 1 | BG37: PS
B38: =+B37+1 -> 26 | G38: =IF(ISERROR(AVERAGE(F$13:F38)),"n/a",AVERAGE(F$13:F38)) -> 117 | H38: =G38 -> 117 | O38: =IF(J38=1,"A",IF(K38=1,"B",IF(L38=1,"C",IF(M38=1,"D",IF(N38=1,"E","n/a"))))) -> n/a | V38: =IF(O38="n/a","",IF(O38=U38,1,"")) | W38: =IF(O38="n/a","",IF(O38<>U38,1,"")) | X38: =SUM(V$13:V38)/COUNTA(B$13:B38) -> 0.26923077 | AE38: =+IF($F$4=0,0,IF(W38=1,1,IF(OR(R38*$F$8=1,S38*$F$9=1,F38>=AF38),2,0))) -> #N/A | AF38: =HLOOKUP(C38,$K$6:$O$7,2,FALSE) -> #N/A | BF38: =BB25 -> 0.5 | BG38: DS
B39: =+B38+1 -> 27 | G39: =IF(ISERROR(AVERAGE(F$13:F39)),"n/a",AVERAGE(F$13:F39)) -> 117 | H39: =G39 -> 117 | O39: =IF(J39=1,"A",IF(K39=1,"B",IF(L39=1,"C",IF(M39=1,"D",IF(N39=1,"E","n/a"))))) -> n/a | V39: =IF(O39="n/a","",IF(O39=U39,1,"")) | W39: =IF(O39="n/a","",IF(O39<>U39,1,"")) | X39: =SUM(V$13:V39)/COUNTA(B$13:B39) -> 0.25925926 | AE39: =+IF($F$4=0,0,IF(W39=1,1,IF(OR(R39*$F$8=1,S39*$F$9=1,F39>=AF39),2,0))) -> #N/A | AF39: =HLOOKUP(C39,$K$6:$O$7,2,FALSE) -> #N/A | BF39: =BB28 -> 1 | BG39: RC
B40: =+B39+1 -> 28 | G40: =IF(ISERROR(AVERAGE(F$13:F40)),"n/a",AVERAGE(F$13:F40)) -> 117 | H40: =G40 -> 117 | O40: =IF(J40=1,"A",IF(K40=1,"B",IF(L40=1,"C",IF(M40=1,"D",IF(N40=1,"E","n/a"))))) -> n/a | V40: =IF(O40="n/a","",IF(O40=U40,1,"")) | W40: =IF(O40="n/a","",IF(O40<>U40,1,"")) | X40: =SUM(V$13:V40)/COUNTA(B$13:B40) -> 0.25 | AE40: =+IF($F$4=0,0,IF(W40=1,1,IF(OR(R40*$F$8=1,S40*$F$9=1,F40>=AF40),2,0))) -> #N/A | AF40: =HLOOKUP(C40,$K$6:$O$7,2,FALSE) -> #N/A | BF40: =BB31 -> 0.5 | BG40: CR
B41: =+B40+1 -> 29 | G41: =IF(ISERROR(AVERAGE(F$13:F41)),"n/a",AVERAGE(F$13:F41)) -> 117 | H41: =G41 -> 117 | O41: =IF(J41=1,"A",IF(K41=1,"B",IF(L41=1,"C",IF(M41=1,"D",IF(N41=1,"E","n/a"))))) -> n/a | V41: =IF(O41="n/a","",IF(O41=U41,1,"")) | W41: =IF(O41="n/a","",IF(O41<>U41,1,"")) | X41: =SUM(V$13:V41)/COUNTA(B$13:B41) -> 0.24137931 | AE41: =+IF($F$4=0,0,IF(W41=1,1,IF(OR(R41*$F$8=1,S41*$F$9=1,F41>=AF41),2,0))) -> #N/A | AF41: =HLOOKUP(C41,$K$6:$O$7,2,FALSE) -> #N/A | BF41: =BB34 -> 0.5 | BG41: SC
B42: =+B41+1 -> 30 | G42: =IF(ISERROR(AVERAGE(F$13:F42)),"n/a",AVERAGE(F$13:F42)) -> 117 | H42: =G42 -> 117 | O42: =IF(J42=1,"A",IF(K42=1,"B",IF(L42=1,"C",IF(M42=1,"D",IF(N42=1,"E","n/a"))))) -> n/a | V42: =IF(O42="n/a","",IF(O42=U42,1,"")) | W42: =IF(O42="n/a","",IF(O42<>U42,1,"")) | X42: =SUM(V$13:V42)/COUNTA(B$13:B42) -> 0.23333333 | AE42: =+IF($F$4=0,0,IF(W42=1,1,IF(OR(R42*$F$8=1,S42*$F$9=1,F42>=AF42),2,0))) -> #N/A | AF42: =HLOOKUP(C42,$K$6:$O$7,2,FALSE) -> #N/A
...

Sheet Source_Input (2)
B2: ="GMAT Error Log"&" - "&F5 -> GMAT Error Log - Source 2
B4: Highlight Errors? (1=YES, 0=NO) | F4: 1
B5: Question Source: | F5: Source 2
B6: Highlighting conditions: | J6: Tot. | K6: PS | L6: DS | M6: RC | N6: CR | O6: SC
B7: Time (anything greater than or equal to X secs.): | J7: =IF(ISERROR(SUMPRODUCT(K7:O7,J1017:N1017)),"n/a",SUMPRODUCT(K7:O7,J1017:N1017)) -> n/a | K7: ='Source_Input (1)'!K7 -> 120 | L7: ='Source_Input (1)'!L7 -> 120 | M7: ='Source_Input (1)'!M7 -> 120 | N7: ='Source_Input (1)'!N7 -> 120 | O7: ='Source_Input (1)'!O7 -> 120
B8: POE / Medium comfort (1=YES, 0=NO) | F8: ='Source_Input (1)'!F8 -> 1
B9: Guess / No comfort (1=YES, 0=NO) | F9: ='Source_Input (1)'!F9 -> 1
AE10: DO NOT DELETE THESE COLUMNS
B11: Question | C11: Question | G11: Cum. Avg | H11: 10Q Avg | J11: Answer Choice | Q11: Answer Selection Method / Comfort | U11: Answer Result | Z11: Why Wrong? | AE11: CONDITIONAL | AF11: GOAL | AR11: =F5&" Performance Report" -> Source 2 Performance Report
B12: Number | C12: Type | E12: Date | F12: Time (s) | G12: Time (s) | H12: Time (s) | J12: A | K12: B | L12: C | M12: D | N12: E | Q12: Know | R12: POE | S12: Guess | U12: Correct Ans. | V12: Correct | W12: Incorrect | X12: % Correct | Z12: Concept | AA12: Stupid Error | AC12: Notes (helpful to write down question topic of any incorrect answers) | AE12: FORMATING | AF12: TIME
B13: 1 | G13: =IF(ISERROR(AVERAGE(F$13:F13)),"n/a",AVERAGE(F$13:F13)) -> n/a | H13: =G13 -> n/a | I13: - | O13: =IF(J13=1,"A",IF(K13=1,"B",IF(L13=1,"C",IF(M13=1,"D",IF(N13=1,"E","n/a"))))) -> n/a | V13: =IF(O13="n/a","",IF(O13=U13,1,"")) | W13: =IF(O13="n/a","",IF(O13<>U13,1,"")) | X13: =SUM(V$13:V13)/COUNTA(B$13:B13) -> 0 | AE13: =+IF($F$4=0,0,IF(W13=1,1,IF(OR(R13*$F$8=1,S13*$F$9=1,F13>=AF13),2,0))) -> #N/A | AF13: =HLOOKUP(C13,$K$6:$O$7,2,FALSE) -> #N/A
B14: =+B13+1 -> 2 | G14: =IF(ISERROR(AVERAGE(F$13:F14)),"n/a",AVERAGE(F$13:F14)) -> n/a | H14: =G14 -> n/a | O14: =IF(J14=1,"A",IF(K14=1,"B",IF(L14=1,"C",IF(M14=1,"D",IF(N14=1,"E","n/a"))))) -> n/a | V14: =IF(O14="n/a","",IF(O14=U14,1,"")) | W14: =IF(O14="n/a","",IF(O14<>U14,1,"")) | X14: =SUM(V$13:V14)/COUNTA(B$13:B14) -> 0 | AE14: =+IF($F$4=0,0,IF(W14=1,1,IF(OR(R14*$F$8=1,S14*$F$9=1,F14>=AF14),2,0))) -> #N/A | AF14: =HLOOKUP(C14,$K$6:$O$7,2,FALSE) -> #N/A | AR14: Date of Report: | AU14: =NOW() -> 40134.633
B15: =+B14+1 -> 3 | G15: =IF(ISERROR(AVERAGE(F$13:F15)),"n/a",AVERAGE(F$13:F15)) -> n/a | H15: =G15 -> n/a | O15: =IF(J15=1,"A",IF(K15=1,"B",IF(L15=1,"C",IF(M15=1,"D",IF(N15=1,"E","n/a"))))) -> n/a | V15: =IF(O15="n/a","",IF(O15=U15,1,"")) | W15: =IF(O15="n/a","",IF(O15<>U15,1,"")) | X15: =SUM(V$13:V15)/COUNTA(B$13:B15) -> 0 | AE15: =+IF($F$4=0,0,IF(W15=1,1,IF(OR(R15*$F$8=1,S15*$F$9=1,F15>=AF15),2,0))) -> #N/A | AF15: =HLOOKUP(C15,$K$6:$O$7,2,FALSE) -> #N/A
B16: =+B15+1 -> 4 | G16: =IF(ISERROR(AVERAGE(F$13:F16)),"n/a",AVERAGE(F$13:F16)) -> n/a | H16: =G16 -> n/a | O16: =IF(J16=1,"A",IF(K16=1,"B",IF(L16=1,"C",IF(M16=1,"D",IF(N16=1,"E","n/a"))))) -> n/a | V16: =IF(O16="n/a","",IF(O16=U16,1,"")) | W16: =IF(O16="n/a","",IF(O16<>U16,1,"")) | X16: =SUM(V$13:V16)/COUNTA(B$13:B16) -> 0 | AE16: =+IF($F$4=0,0,IF(W16=1,1,IF(OR(R16*$F$8=1,S16*$F$9=1,F16>=AF16),2,0))) -> #N/A | AF16: =HLOOKUP(C16,$K$6:$O$7,2,FALSE) -> #N/A
B17: =+B16+1 -> 5 | G17: =IF(ISERROR(AVERAGE(F$13:F17)),"n/a",AVERAGE(F$13:F17)) -> n/a | H17: =G17 -> n/a | O17: =IF(J17=1,"A",IF(K17=1,"B",IF(L17=1,"C",IF(M17=1,"D",IF(N17=1,"E","n/a"))))) -> n/a | V17: =IF(O17="n/a","",IF(O17=U17,1,"")) | W17: =IF(O17="n/a","",IF(O17<>U17,1,"")) | X17: =SUM(V$13:V17)/COUNTA(B$13:B17) -> 0 | AE17: =+IF($F$4=0,0,IF(W17=1,1,IF(OR(R17*$F$8=1,S17*$F$9=1,F17>=AF17),2,0))) -> #N/A | AF17: =HLOOKUP(C17,$K$6:$O$7,2,FALSE) -> #N/A | AU17: Correct | AV17: Know | AW17: POE | AX17: Guess | AY17: Incorrect | AZ17: Concept | BA17: Stpd Error | BB17: Accuracy | BC17: Timing | BD17: +/- Goal
B18: =+B17+1 -> 6 | G18: =IF(ISERROR(AVERAGE(F$13:F18)),"n/a",AVERAGE(F$13:F18)) -> n/a | H18: =G18 -> n/a | O18: =IF(J18=1,"A",IF(K18=1,"B",IF(L18=1,"C",IF(M18=1,"D",IF(N18=1,"E","n/a"))))) -> n/a | V18: =IF(O18="n/a","",IF(O18=U18,1,"")) | W18: =IF(O18="n/a","",IF(O18<>U18,1,"")) | X18: =SUM(V$13:V18)/COUNTA(B$13:B18) -> 0 | AE18: =+IF($F$4=0,0,IF(W18=1,1,IF(OR(R18*$F$8=1,S18*$F$9=1,F18>=AF18),2,0))) -> #N/A | AF18: =HLOOKUP(C18,$K$6:$O$7,2,FALSE) -> #N/A | AR18: All Questions | AU18: =V1015 -> 0 | AV18: =Q1015 -> 0 | AW18: =R1015 -> 0 | AX18: =S1015 -> 0 | AY18: =W1015 -> 0 | AZ18: =Z1015 -> 0 | BA18: =AA1015 -> 0 | BB18: =IF(ISERROR(AU18/(AU18+AY18)),"n/a",AU18/(AU18+AY18)) -> n/a | BC18: =IF(ISERROR(TEXT($E$1023,"00")&":"&TEXT($F$1023,"00")),"n/a",TEXT($E$1023,"00")&":"&TEXT($F$1023,"00")) -> n/a | BD18: =IF(ISERROR(BF18&TEXT($E$1040,"00")&":"&TEXT($F$1040,"00")),"n/a",BF18&TEXT($E$1040,"00")&":"&TEXT($F$1040,"00")) -> n/a | BF18: =IF(F1032<0,"-","+") -> #VALUE!
B19: =+B18+1 -> 7 | G19: =IF(ISERROR(AVERAGE(F$13:F19)),"n/a",AVERAGE(F$13:F19)) -> n/a | H19: =G19 -> n/a | O19: =IF(J19=1,"A",IF(K19=1,"B",IF(L19=1,"C",IF(M19=1,"D",IF(N19=1,"E","n/a"))))) -> n/a | V19: =IF(O19="n/a","",IF(O19=U19,1,"")) | W19: =IF(O19="n/a","",IF(O19<>U19,1,"")) | X19: =SUM(V$13:V19)/COUNTA(B$13:B19) -> 0 | AE19: =+IF($F$4=0,0,IF(W19=1,1,IF(OR(R19*$F$8=1,S19*$F$9=1,F19>=AF19),2,0))) -> #N/A | AF19: =HLOOKUP(C19,$K$6:$O$7,2,FALSE) -> #N/A | AV19: =+IF(ISERROR(AV18/SUM($AU$18,$AY$18)),"n/a",AV18/SUM($AU$18,$AY$18)) -> n/a | AW19: =+IF(ISERROR(AW18/SUM($AU$18,$AY$18)),"n/a",AW18/SUM($AU$18,$AY$18)) -> n/a | AX19: =+IF(ISERROR(AX18/SUM($AU$18,$AY$18)),"n/a",AX18/SUM($AU$18,$AY$18)) -> n/a | AZ19: =+IF(ISERROR(AZ18/$AY$18),"n/a",AZ18/$AY$18) -> n/a | BA19: =+IF(ISERROR(BA18/$AY$18),"n/a",BA18/$AY$18) -> n/a
B20: =+B19+1 -> 8 | G20: =IF(ISERROR(AVERAGE(F$13:F20)),"n/a",AVERAGE(F$13:F20)) -> n/a | H20: =G20 -> n/a | O20: =IF(J20=1,"A",IF(K20=1,"B",IF(L20=1,"C",IF(M20=1,"D",IF(N20=1,"E","n/a"))))) -> n/a | V20: =IF(O20="n/a","",IF(O20=U20,1,"")) | W20: =IF(O20="n/a","",IF(O20<>U20,1,"")) | X20: =SUM(V$13:V20)/COUNTA(B$13:B20) -> 0 | AE20: =+IF($F$4=0,0,IF(W20=1,1,IF(OR(R20*$F$8=1,S20*$F$9=1,F20>=AF20),2,0))) -> #N/A | AF20: =HLOOKUP(C20,$K$6:$O$7,2,FALSE) -> #N/A | AR20: Performance by Question Type
B21: =+B20+1 -> 9 | G21: =IF(ISERROR(AVERAGE(F$13:F21)),"n/a",AVERAGE(F$13:F21)) -> n/a | H21: =G21 -> n/a | O21: =IF(J21=1,"A",IF(K21=1,"B",IF(L21=1,"C",IF(M21=1,"D",IF(N21=1,"E","n/a"))))) -> n/a | V21: =IF(O21="n/a","",IF(O21=U21,1,"")) | W21: =IF(O21="n/a","",IF(O21<>U21,1,"")) | X21: =SUM(V$13:V21)/COUNTA(B$13:B21) -> 0 | AE21: =+IF($F$4=0,0,IF(W21=1,1,IF(OR(R21*$F$8=1,S21*$F$9=1,F21>=AF21),2,0))) -> #N/A | AF21: =HLOOKUP(C21,$K$6:$O$7,2,FALSE) -> #N/A
B22: =+B21+1 -> 10 | G22: =IF(ISERROR(AVERAGE(F$13:F22)),"n/a",AVERAGE(F$13:F22)) -> n/a | H22: =G22 -> n/a | O22: =IF(J22=1,"A",IF(K22=1,"B",IF(L22=1,"C",IF(M22=1,"D",IF(N22=1,"E","n/a"))))) -> n/a | V22: =IF(O22="n/a","",IF(O22=U22,1,"")) | W22: =IF(O22="n/a","",IF(O22<>U22,1,"")) | X22: =SUM(V$13:V22)/COUNTA(B$13:B22) -> 0 | AE22: =+IF($F$4=0,0,IF(W22=1,1,IF(OR(R22*$F$8=1,S22*$F$9=1,F22>=AF22),2,0))) -> #N/A | AF22: =HLOOKUP(C22,$K$6:$O$7,2,FALSE) -> #N/A | AR22: Problem Solving | AU22: =V1017 -> 0 | AV22: =Q1017 -> 0 | AW22: =R1017 -> 0 | AX22: =S1017 -> 0 | AY22: =$W$1017 -> 0 | AZ22: =Z1017 -> 0 | BA22: =AA1017 -> 0 | BB22: =IF(ISERROR(AU22/(AU22+AY22)),"n/a",AU22/(AU22+AY22)) -> n/a | BC22: =IF(ISERROR(TEXT($E$1025,"00")&":"&TEXT($F$1025,"00")),"n/a",TEXT($E$1025,"00")&":"&TEXT($F$1025,"00")) -> n/a | BD22: =IF(ISERROR(BF22&TEXT($E$1042,"00")&":"&TEXT($F$1042,"00")),"n/a",BF22&TEXT($E$1042,"00")&":"&TEXT($F$1042,"00")) -> n/a | BF22: =IF(F1034<0,"-","+") -> #VALUE!
B23: =+B22+1 -> 11 | G23: =IF(ISERROR(AVERAGE(F$13:F23)),"n/a",AVERAGE(F$13:F23)) -> n/a | H23: =G23 -> n/a | O23: =IF(J23=1,"A",IF(K23=1,"B",IF(L23=1,"C",IF(M23=1,"D",IF(N23=1,"E","n/a"))))) -> n/a | V23: =IF(O23="n/a","",IF(O23=U23,1,"")) | W23: =IF(O23="n/a","",IF(O23<>U23,1,"")) | X23: =SUM(V$13:V23)/COUNTA(B$13:B23) -> 0 | AE23: =+IF($F$4=0,0,IF(W23=1,1,IF(OR(R23*$F$8=1,S23*$F$9=1,F23>=AF23),2,0))) -> #N/A | AF23: =HLOOKUP(C23,$K$6:$O$7,2,FALSE) -> #N/A | AV23: =+IF(ISERROR(AV22/SUM($AU$22,$AY$22)),"n/a",AV22/SUM($AU$22,$AY$22)) -> n/a | AW23: =+IF(ISERROR(AW22/SUM($AU$22,$AY$22)),"n/a",AW22/SUM($AU$22,$AY$22)) -> n/a | AX23: =+IF(ISERROR(AX22/SUM($AU$22,$AY$22)),"n/a",AX22/SUM($AU$22,$AY$22)) -> n/a | AZ23: =+IF(ISERROR(AZ22/$AY$22),"n/a",AZ22/$AY$22) -> n/a | BA23: =+IF(ISERROR(BA22/$AY$22),"n/a",BA22/$AY$22) -> n/a
B24: =+B23+1 -> 12 | G24: =IF(ISERROR(AVERAGE(F$13:F24)),"n/a",AVERAGE(F$13:F24)) -> n/a | H24: =G24 -> n/a | O24: =IF(J24=1,"A",IF(K24=1,"B",IF(L24=1,"C",IF(M24=1,"D",IF(N24=1,"E","n/a"))))) -> n/a | V24: =IF(O24="n/a","",IF(O24=U24,1,"")) | W24: =IF(O24="n/a","",IF(O24<>U24,1,"")) | X24: =SUM(V$13:V24)/COUNTA(B$13:B24) -> 0 | AE24: =+IF($F$4=0,0,IF(W24=1,1,IF(OR(R24*$F$8=1,S24*$F$9=1,F24>=AF24),2,0))) -> #N/A | AF24: =HLOOKUP(C24,$K$6:$O$7,2,FALSE) -> #N/A
B25: =+B24+1 -> 13 | G25: =IF(ISERROR(AVERAGE(F$13:F25)),"n/a",AVERAGE(F$13:F25)) -> n/a | H25: =G25 -> n/a | O25: =IF(J25=1,"A",IF(K25=1,"B",IF(L25=1,"C",IF(M25=1,"D",IF(N25=1,"E","n/a"))))) -> n/a | V25: =IF(O25="n/a","",IF(O25=U25,1,"")) | W25: =IF(O25="n/a","",IF(O25<>U25,1,"")) | X25: =SUM(V$13:V25)/COUNTA(B$13:B25) -> 0 | AE25: =+IF($F$4=0,0,IF(W25=1,1,IF(OR(R25*$F$8=1,S25*$F$9=1,F25>=AF25),2,0))) -> #N/A | AF25: =HLOOKUP(C25,$K$6:$O$7,2,FALSE) -> #N/A | AR25: Data Sufficiency | AU25: =$V$1018 -> 0 | AV25: =Q1018 -> 0 | AW25: =R1018 -> 0 | AX25: =S1018 -> 0 | AY25: =$W$1018 -> 0 | AZ25: =Z1018 -> 0 | BA25: =AA1018 -> 0 | BB25: =IF(ISERROR(AU25/(AU25+AY25)),"n/a",AU25/(AU25+AY25)) -> n/a | BC25: =IF(ISERROR(TEXT($E$1026,"00")&":"&TEXT($F$1026,"00")),"n/a",TEXT($E$1026,"00")&":"&TEXT($F$1026,"00")) -> n/a | BD25: =IF(ISERROR(BF25&TEXT($E$1043,"00")&":"&TEXT($F$1043,"00")),"n/a",BF25&TEXT($E$1043,"00")&":"&TEXT($F$1043,"00")) -> n/a | BF25: =IF(F1035<0,"-","+") -> #VALUE!
B26: =+B25+1 -> 14 | G26: =IF(ISERROR(AVERAGE(F$13:F26)),"n/a",AVERAGE(F$13:F26)) -> n/a | H26: =G26 -> n/a | O26: =IF(J26=1,"A",IF(K26=1,"B",IF(L26=1,"C",IF(M26=1,"D",IF(N26=1,"E","n/a"))))) -> n/a | V26: =IF(O26="n/a","",IF(O26=U26,1,"")) | W26: =IF(O26="n/a","",IF(O26<>U26,1,"")) | X26: =SUM(V$13:V26)/COUNTA(B$13:B26) -> 0 | AE26: =+IF($F$4=0,0,IF(W26=1,1,IF(OR(R26*$F$8=1,S26*$F$9=1,F26>=AF26),2,0))) -> #N/A | AF26: =HLOOKUP(C26,$K$6:$O$7,2,FALSE) -> #N/A | AV26: =+IF(ISERROR(AV25/SUM($AU$25,$AY$25)),"n/a",AV25/SUM($AU$25,$AY$25)) -> n/a | AW26: =+IF(ISERROR(AW25/SUM($AU$25,$AY$25)),"n/a",AW25/SUM($AU$25,$AY$25)) -> n/a | AX26: =+IF(ISERROR(AX25/SUM($AU$25,$AY$25)),"n/a",AX25/SUM($AU$25,$AY$25)) -> n/a | AZ26: =+IF(ISERROR(AZ25/$AY$25),"n/a",AZ25/$AY$25) -> n/a | BA26: =+IF(ISERROR(BA25/$AY$25),"n/a",BA25/$AY$25) -> n/a
B27: =+B26+1 -> 15 | G27: =IF(ISERROR(AVERAGE(F$13:F27)),"n/a",AVERAGE(F$13:F27)) -> n/a | H27: =G27 -> n/a | O27: =IF(J27=1,"A",IF(K27=1,"B",IF(L27=1,"C",IF(M27=1,"D",IF(N27=1,"E","n/a"))))) -> n/a | V27: =IF(O27="n/a","",IF(O27=U27,1,"")) | W27: =IF(O27="n/a","",IF(O27<>U27,1,"")) | X27: =SUM(V$13:V27)/COUNTA(B$13:B27) -> 0 | AE27: =+IF($F$4=0,0,IF(W27=1,1,IF(OR(R27*$F$8=1,S27*$F$9=1,F27>=AF27),2,0))) -> #N/A | AF27: =HLOOKUP(C27,$K$6:$O$7,2,FALSE) -> #N/A
B28: =+B27+1 -> 16 | G28: =IF(ISERROR(AVERAGE(F$13:F28)),"n/a",AVERAGE(F$13:F28)) -> n/a | H28: =G28 -> n/a | O28: =IF(J28=1,"A",IF(K28=1,"B",IF(L28=1,"C",IF(M28=1,"D",IF(N28=1,"E","n/a"))))) -> n/a | V28: =IF(O28="n/a","",IF(O28=U28,1,"")) | W28: =IF(O28="n/a","",IF(O28<>U28,1,"")) | X28: =SUM(V$13:V28)/COUNTA(B$13:B28) -> 0 | AE28: =+IF($F$4=0,0,IF(W28=1,1,IF(OR(R28*$F$8=1,S28*$F$9=1,F28>=AF28),2,0))) -> #N/A | AF28: =HLOOKUP(C28,$K$6:$O$7,2,FALSE) -> #N/A | AR28: Reading Comprehension | AU28: =$V$1019 -> 0 | AV28: =Q1019 -> 0 | AW28: =R1019 -> 0 | AX28: =S1019 -> 0 | AY28: =$W$1019 -> 0 | AZ28: =Z1019 -> 0 | BA28: =AA1019 -> 0 | BB28: =IF(ISERROR(AU28/(AU28+AY28)),"n/a",AU28/(AU28+AY28)) -> n/a | BC28: =IF(ISERROR(TEXT($E$1027,"00")&":"&TEXT($F$1027,"00")),"n/a",TEXT($E$1027,"00")&":"&TEXT($F$1027,"00")) -> n/a | BD28: =IF(ISERROR(BF28&TEXT($E$1044,"00")&":"&TEXT($F$1044,"00")),"n/a",BF28&TEXT($E$1044,"00")&":"&TEXT($F$1044,"00")) -> n/a | BF28: =IF(F1036<0,"-","+") -> #VALUE!
B29: =+B28+1 -> 17 | G29: =IF(ISERROR(AVERAGE(F$13:F29)),"n/a",AVERAGE(F$13:F29)) -> n/a | H29: =G29 -> n/a | O29: =IF(J29=1,"A",IF(K29=1,"B",IF(L29=1,"C",IF(M29=1,"D",IF(N29=1,"E","n/a"))))) -> n/a | V29: =IF(O29="n/a","",IF(O29=U29,1,"")) | W29: =IF(O29="n/a","",IF(O29<>U29,1,"")) | X29: =SUM(V$13:V29)/COUNTA(B$13:B29) -> 0 | AE29: =+IF($F$4=0,0,IF(W29=1,1,IF(OR(R29*$F$8=1,S29*$F$9=1,F29>=AF29),2,0))) -> #N/A | AF29: =HLOOKUP(C29,$K$6:$O$7,2,FALSE) -> #N/A | AV29: =+IF(ISERROR(AV28/SUM($AU$28,$AY$28)),"n/a",AV28/SUM($AU$28,$AY$28)) -> n/a | AW29: =+IF(ISERROR(AW28/SUM($AU$28,$AY$28)),"n/a",AW28/SUM($AU$28,$AY$28)) -> n/a | AX29: =+IF(ISERROR(AX28/SUM($AU$28,$AY$28)),"n/a",AX28/SUM($AU$28,$AY$28)) -> n/a | AZ29: =+IF(ISERROR(AZ28/$AY$28),"n/a",AZ28/$AY$28) -> n/a | BA29: =+IF(ISERROR(BA28/$AY$28),"n/a",BA28/$AY$28) -> n/a
B30: =+B29+1 -> 18 | G30: =IF(ISERROR(AVERAGE(F$13:F30)),"n/a",AVERAGE(F$13:F30)) -> n/a | H30: =G30 -> n/a | O30: =IF(J30=1,"A",IF(K30=1,"B",IF(L30=1,"C",IF(M30=1,"D",IF(N30=1,"E","n/a"))))) -> n/a | V30: =IF(O30="n/a","",IF(O30=U30,1,"")) | W30: =IF(O30="n/a","",IF(O30<>U30,1,"")) | X30: =SUM(V$13:V30)/COUNTA(B$13:B30) -> 0 | AE30: =+IF($F$4=0,0,IF(W30=1,1,IF(OR(R30*$F$8=1,S30*$F$9=1,F30>=AF30),2,0))) -> #N/A | AF30: =HLOOKUP(C30,$K$6:$O$7,2,FALSE) -> #N/A
B31: =+B30+1 -> 19 | G31: =IF(ISERROR(AVERAGE(F$13:F31)),"n/a",AVERAGE(F$13:F31)) -> n/a | H31: =G31 -> n/a | O31: =IF(J31=1,"A",IF(K31=1,"B",IF(L31=1,"C",IF(M31=1,"D",IF(N31=1,"E","n/a"))))) -> n/a | V31: =IF(O31="n/a","",IF(O31=U31,1,"")) | W31: =IF(O31="n/a","",IF(O31<>U31,1,"")) | X31: =SUM(V$13:V31)/COUNTA(B$13:B31) -> 0 | AE31: =+IF($F$4=0,0,IF(W31=1,1,IF(OR(R31*$F$8=1,S31*$F$9=1,F31>=AF31),2,0))) -> #N/A | AF31: =HLOOKUP(C31,$K$6:$O$7,2,FALSE) -> #N/A | AR31: Critical Reasoning | AU31: =$V$1020 -> 0 | AV31: =Q1020 -> 0 | AW31: =R1020 -> 0 | AX31: =S1020 -> 0 | AY31: =$W$1020 -> 0 | AZ31: =Z1020 -> 0 | BA31: =AA1020 -> 0 | BB31: =IF(ISERROR(AU31/(AU31+AY31)),"n/a",AU31/(AU31+AY31)) -> n/a | BC31: =IF(ISERROR(TEXT($E$1028,"00")&":"&TEXT($F$1028,"00")),"n/a",TEXT($E$1028,"00")&":"&TEXT($F$1028,"00")) -> n/a | BD31: =IF(ISERROR(BF31&TEXT($E$1045,"00")&":"&TEXT($F$1045,"00")),"n/a",BF31&TEXT($E$1045,"00")&":"&TEXT($F$1045,"00")) -> n/a | BF31: =IF(F1037<0,"-","+") -> #VALUE!
B32: =+B31+1 -> 20 | G32: =IF(ISERROR(AVERAGE(F$13:F32)),"n/a",AVERAGE(F$13:F32)) -> n/a | H32: =G32 -> n/a | O32: =IF(J32=1,"A",IF(K32=1,"B",IF(L32=1,"C",IF(M32=1,"D",IF(N32=1,"E","n/a"))))) -> n/a | V32: =IF(O32="n/a","",IF(O32=U32,1,"")) | W32: =IF(O32="n/a","",IF(O32<>U32,1,"")) | X32: =SUM(V$13:V32)/COUNTA(B$13:B32) -> 0 | AE32: =+IF($F$4=0,0,IF(W32=1,1,IF(OR(R32*$F$8=1,S32*$F$9=1,F32>=AF32),2,0))) -> #N/A | AF32: =HLOOKUP(C32,$K$6:$O$7,2,FALSE) -> #N/A | AV32: =+IF(ISERROR(AV31/SUM($AU$31,$AY$31)),"n/a",AV31/SUM($AU$31,$AY$31)) -> n/a | AW32: =+IF(ISERROR(AW31/SUM($AU$31,$AY$31)),"n/a",AW31/SUM($AU$31,$AY$31)) -> n/a | AX32: =+IF(ISERROR(AX31/SUM($AU$31,$AY$31)),"n/a",AX31/SUM($AU$31,$AY$31)) -> n/a | AZ32: =+IF(ISERROR(AZ31/$AY$31),"n/a",AZ31/$AY$31) -> n/a | BA32: =+IF(ISERROR(BA31/$AY$31),"n/a",BA31/$AY$31) -> n/a
B33: =+B32+1 -> 21 | G33: =IF(ISERROR(AVERAGE(F$13:F33)),"n/a",AVERAGE(F$13:F33)) -> n/a | H33: =G33 -> n/a | O33: =IF(J33=1,"A",IF(K33=1,"B",IF(L33=1,"C",IF(M33=1,"D",IF(N33=1,"E","n/a"))))) -> n/a | V33: =IF(O33="n/a","",IF(O33=U33,1,"")) | W33: =IF(O33="n/a","",IF(O33<>U33,1,"")) | X33: =SUM(V$13:V33)/COUNTA(B$13:B33) -> 0 | AE33: =+IF($F$4=0,0,IF(W33=1,1,IF(OR(R33*$F$8=1,S33*$F$9=1,F33>=AF33),2,0))) -> #N/A | AF33: =HLOOKUP(C33,$K$6:$O$7,2,FALSE) -> #N/A
B34: =+B33+1 -> 22 | G34: =IF(ISERROR(AVERAGE(F$13:F34)),"n/a",AVERAGE(F$13:F34)) -> n/a | H34: =G34 -> n/a | O34: =IF(J34=1,"A",IF(K34=1,"B",IF(L34=1,"C",IF(M34=1,"D",IF(N34=1,"E","n/a"))))) -> n/a | V34: =IF(O34="n/a","",IF(O34=U34,1,"")) | W34: =IF(O34="n/a","",IF(O34<>U34,1,"")) | X34: =SUM(V$13:V34)/COUNTA(B$13:B34) -> 0 | AE34: =+IF($F$4=0,0,IF(W34=1,1,IF(OR(R34*$F$8=1,S34*$F$9=1,F34>=AF34),2,0))) -> #N/A | AF34: =HLOOKUP(C34,$K$6:$O$7,2,FALSE) -> #N/A | AR34: Sentence Correction | AU34: =$V$1021 -> 0 | AV34: =Q1021 -> 0 | AW34: =R1021 -> 0 | AX34: =S1021 -> 0 | AY34: =$W$1021 -> 0 | AZ34: =Z1021 -> 0 | BA34: =AA1021 -> 0 | BB34: =IF(ISERROR(AU34/(AU34+AY34)),"n/a",AU34/(AU34+AY34)) -> n/a | BC34: =IF(ISERROR(TEXT($E$1029,"00")&":"&TEXT($F$1029,"00")),"n/a",TEXT($E$1029,"00")&":"&TEXT($F$1029,"00")) -> n/a | BD34: =IF(ISERROR(BF34&TEXT($E$1046,"00")&":"&TEXT($F$1046,"00")),"n/a",BF34&TEXT($E$1046,"00")&":"&TEXT($F$1046,"00")) -> n/a | BF34: =IF(F1038<0,"-","+") -> #VALUE!
B35: =+B34+1 -> 23 | G35: =IF(ISERROR(AVERAGE(F$13:F35)),"n/a",AVERAGE(F$13:F35)) -> n/a | H35: =G35 -> n/a | O35: =IF(J35=1,"A",IF(K35=1,"B",IF(L35=1,"C",IF(M35=1,"D",IF(N35=1,"E","n/a"))))) -> n/a | V35: =IF(O35="n/a","",IF(O35=U35,1,"")) | W35: =IF(O35="n/a","",IF(O35<>U35,1,"")) | X35: =SUM(V$13:V35)/COUNTA(B$13:B35) -> 0 | AE35: =+IF($F$4=0,0,IF(W35=1,1,IF(OR(R35*$F$8=1,S35*$F$9=1,F35>=AF35),2,0))) -> #N/A | AF35: =HLOOKUP(C35,$K$6:$O$7,2,FALSE) -> #N/A | AV35: =+IF(ISERROR(AV34/SUM($AU$34,$AY$34)),"n/a",AV34/SUM($AU$34,$AY$34)) -> n/a | AW35: =+IF(ISERROR(AW34/SUM($AU$34,$AY$34)),"n/a",AW34/SUM($AU$34,$AY$34)) -> n/a | AX35: =+IF(ISERROR(AX34/SUM($AU$34,$AY$34)),"n/a",AX34/SUM($AU$34,$AY$34)) -> n/a | AZ35: =+IF(ISERROR(AZ34/$AY$34),"n/a",AZ34/$AY$34) -> n/a | BA35: =+IF(ISERROR(BA34/$AY$34),"n/a",BA34/$AY$34) -> n/a
B36: =+B35+1 -> 24 | G36: =IF(ISERROR(AVERAGE(F$13:F36)),"n/a",AVERAGE(F$13:F36)) -> n/a | H36: =G36 -> n/a | O36: =IF(J36=1,"A",IF(K36=1,"B",IF(L36=1,"C",IF(M36=1,"D",IF(N36=1,"E","n/a"))))) -> n/a | V36: =IF(O36="n/a","",IF(O36=U36,1,"")) | W36: =IF(O36="n/a","",IF(O36<>U36,1,"")) | X36: =SUM(V$13:V36)/COUNTA(B$13:B36) -> 0 | AE36: =+IF($F$4=0,0,IF(W36=1,1,IF(OR(R36*$F$8=1,S36*$F$9=1,F36>=AF36),2,0))) -> #N/A | AF36: =HLOOKUP(C36,$K$6:$O$7,2,FALSE) -> #N/A | BF36: =BB18 -> n/a | BG36: Total
B37: =+B36+1 -> 25 | G37: =IF(ISERROR(AVERAGE(F$13:F37)),"n/a",AVERAGE(F$13:F37)) -> n/a | H37: =G37 -> n/a | O37: =IF(J37=1,"A",IF(K37=1,"B",IF(L37=1,"C",IF(M37=1,"D",IF(N37=1,"E","n/a"))))) -> n/a | V37: =IF(O37="n/a","",IF(O37=U37,1,"")) | W37: =IF(O37="n/a","",IF(O37<>U37,1,"")) | X37: =SUM(V$13:V37)/COUNTA(B$13:B37) -> 0 | AE37: =+IF($F$4=0,0,IF(W37=1,1,IF(OR(R37*$F$8=1,S37*$F$9=1,F37>=AF37),2,0))) -> #N/A | AF37: =HLOOKUP(C37,$K$6:$O$7,2,FALSE) -> #N/A | BF37: =BB22 -> n/a | BG37: PS
B38: =+B37+1 -> 26 | G38: =IF(ISERROR(AVERAGE(F$13:F38)),"n/a",AVERAGE(F$13:F38)) -> n/a | H38: =G38 -> n/a | O38: =IF(J38=1,"A",IF(K38=1,"B",IF(L38=1,"C",IF(M38=1,"D",IF(N38=1,"E","n/a"))))) -> n/a | V38: =IF(O38="n/a","",IF(O38=U38,1,"")) | W38: =IF(O38="n/a","",IF(O38<>U38,1,"")) | X38: =SUM(V$13:V38)/COUNTA(B$13:B38) -> 0 | AE38: =+IF($F$4=0,0,IF(W38=1,1,IF(OR(R38*$F$8=1,S38*$F$9=1,F38>=AF38),2,0))) -> #N/A | AF38: =HLOOKUP(C38,$K$6:$O$7,2,FALSE) -> #N/A | BF38: =BB25 -> n/a | BG38: DS
B39: =+B38+1 -> 27 | G39: =IF(ISERROR(AVERAGE(F$13:F39)),"n/a",AVERAGE(F$13:F39)) -> n/a | H39: =G39 -> n/a | O39: =IF(J39=1,"A",IF(K39=1,"B",IF(L39=1,"C",IF(M39=1,"D",IF(N39=1,"E","n/a"))))) -> n/a | V39: =IF(O39="n/a","",IF(O39=U39,1,"")) | W39: =IF(O39="n/a","",IF(O39<>U39,1,"")) | X39: =SUM(V$13:V39)/COUNTA(B$13:B39) -> 0 | AE39: =+IF($F$4=0,0,IF(W39=1,1,IF(OR(R39*$F$8=1,S39*$F$9=1,F39>=AF39),2,0))) -> #N/A | AF39: =HLOOKUP(C39,$K$6:$O$7,2,FALSE) -> #N/A | BF39: =BB28 -> n/a | BG39: RC
B40: =+B39+1 -> 28 | G40: =IF(ISERROR(AVERAGE(F$13:F40)),"n/a",AVERAGE(F$13:F40)) -> n/a | H40: =G40 -> n/a | O40: =IF(J40=1,"A",IF(K40=1,"B",IF(L40=1,"C",IF(M40=1,"D",IF(N40=1,"E","n/a"))))) -> n/a | V40: =IF(O40="n/a","",IF(O40=U40,1,"")) | W40: =IF(O40="n/a","",IF(O40<>U40,1,"")) | X40: =SUM(V$13:V40)/COUNTA(B$13:B40) -> 0 | AE40: =+IF($F$4=0,0,IF(W40=1,1,IF(OR(R40*$F$8=1,S40*$F$9=1,F40>=AF40),2,0))) -> #N/A | AF40: =HLOOKUP(C40,$K$6:$O$7,2,FALSE) -> #N/A | BF40: =BB31 -> n/a | BG40: CR
B41: =+B40+1 -> 29 | G41: =IF(ISERROR(AVERAGE(F$13:F41)),"n/a",AVERAGE(F$13:F41)) -> n/a | H41: =G41 -> n/a | O41: =IF(J41=1,"A",IF(K41=1,"B",IF(L41=1,"C",IF(M41=1,"D",IF(N41=1,"E","n/a"))))) -> n/a | V41: =IF(O41="n/a","",IF(O41=U41,1,"")) | W41: =IF(O41="n/a","",IF(O41<>U41,1,"")) | X41: =SUM(V$13:V41)/COUNTA(B$13:B41) -> 0 | AE41: =+IF($F$4=0,0,IF(W41=1,1,IF(OR(R41*$F$8=1,S41*$F$9=1,F41>=AF41),2,0))) -> #N/A | AF41: =HLOOKUP(C41,$K$6:$O$7,2,FALSE) -> #N/A | BF41: =BB34 -> n/a | BG41: SC
B42: =+B41+1 -> 30 | G42: =IF(ISERROR(AVERAGE(F$13:F42)),"n/a",AVERAGE(F$13:F42)) -> n/a | H42: =G42 -> n/a | O42: =IF(J42=1,"A",IF(K42=1,"B",IF(L42=1,"C",IF(M42=1,"D",IF(N42=1,"E","n/a"))))) -> n/a | V42: =IF(O42="n/a","",IF(O42=U42,1,"")) | W42: =IF(O42="n/a","",IF(O42<>U42,1,"")) | X42: =SUM(V$13:V42)/COUNTA(B$13:B42) -> 0 | AE42: =+IF($F$4=0,0,IF(W42=1,1,IF(OR(R42*$F$8=1,S42*$F$9=1,F42>=AF42),2,0))) -> #N/A | AF42: =HLOOKUP(C42,$K$6:$O$7,2,FALSE) -> #N/A
...

Sheet Source_Input (3)
B2: ="GMAT Error Log"&" - "&F5 -> GMAT Error Log - Source 3
B4: Highlight Errors? (1=YES, 0=NO) | F4: 1
B5: Question Source: | F5: Source 3
B6: Highlighting conditions: | J6: Tot. | K6: PS | L6: DS | M6: RC | N6: CR | O6: SC
B7: Time (anything greater than or equal to X secs.): | J7: =IF(ISERROR(SUMPRODUCT(K7:O7,J1017:N1017)),"n/a",SUMPRODUCT(K7:O7,J1017:N1017)) -> n/a | K7: ='Source_Input (1)'!K7 -> 120 | L7: ='Source_Input (1)'!L7 -> 120 | M7: ='Source_Input (1)'!M7 -> 120 | N7: ='Source_Input (1)'!N7 -> 120 | O7: ='Source_Input (1)'!O7 -> 120
B8: POE / Medium comfort (1=YES, 0=NO) | F8: ='Source_Input (1)'!F8 -> 1
B9: Guess / No comfort (1=YES, 0=NO) | F9: ='Source_Input (1)'!F9 -> 1
AE10: DO NOT DELETE THESE COLUMNS
B11: Question | C11: Question | G11: Cum. Avg | H11: 10Q Avg | J11: Answer Choice | Q11: Answer Selection Method / Comfort | U11: Answer Result | Z11: Why Wrong? | AE11: CONDITIONAL | AF11: GOAL | AR11: =F5&" Performance Report" -> Source 3 Performance Report
B12: Number | C12: Type | E12: Date | F12: Time (s) | G12: Time (s) | H12: Time (s) | J12: A | K12: B | L12: C | M12: D | N12: E | Q12: Know | R12: POE | S12: Guess | U12: Correct Ans. | V12: Correct | W12: Incorrect | X12: % Correct | Z12: Concept | AA12: Stupid Error | AC12: Notes (helpful to write down question topic of any incorrect answers) | AE12: FORMATING | AF12: TIME
B13: 1 | G13: =IF(ISERROR(AVERAGE(F$13:F13)),"n/a",AVERAGE(F$13:F13)) -> n/a | H13: =G13 -> n/a | I13: - | O13: =IF(J13=1,"A",IF(K13=1,"B",IF(L13=1,"C",IF(M13=1,"D",IF(N13=1,"E","n/a"))))) -> n/a | V13: =IF(O13="n/a","",IF(O13=U13,1,"")) | W13: =IF(O13="n/a","",IF(O13<>U13,1,"")) | X13: =SUM(V$13:V13)/COUNTA(B$13:B13) -> 0 | AE13: =+IF($F$4=0,0,IF(W13=1,1,IF(OR(R13*$F$8=1,S13*$F$9=1,F13>=AF13),2,0))) -> #N/A | AF13: =HLOOKUP(C13,$K$6:$O$7,2,FALSE) -> #N/A
B14: =+B13+1 -> 2 | G14: =IF(ISERROR(AVERAGE(F$13:F14)),"n/a",AVERAGE(F$13:F14)) -> n/a | H14: =G14 -> n/a | O14: =IF(J14=1,"A",IF(K14=1,"B",IF(L14=1,"C",IF(M14=1,"D",IF(N14=1,"E","n/a"))))) -> n/a | V14: =IF(O14="n/a","",IF(O14=U14,1,"")) | W14: =IF(O14="n/a","",IF(O14<>U14,1,"")) | X14: =SUM(V$13:V14)/COUNTA(B$13:B14) -> 0 | AE14: =+IF($F$4=0,0,IF(W14=1,1,IF(OR(R14*$F$8=1,S14*$F$9=1,F14>=AF14),2,0))) -> #N/A | AF14: =HLOOKUP(C14,$K$6:$O$7,2,FALSE) -> #N/A | AR14: Date of Report: | AU14: =NOW() -> 40134.633
B15: =+B14+1 -> 3 | G15: =IF(ISERROR(AVERAGE(F$13:F15)),"n/a",AVERAGE(F$13:F15)) -> n/a | H15: =G15 -> n/a | O15: =IF(J15=1,"A",IF(K15=1,"B",IF(L15=1,"C",IF(M15=1,"D",IF(N15=1,"E","n/a"))))) -> n/a | V15: =IF(O15="n/a","",IF(O15=U15,1,"")) | W15: =IF(O15="n/a","",IF(O15<>U15,1,"")) | X15: =SUM(V$13:V15)/COUNTA(B$13:B15) -> 0 | AE15: =+IF($F$4=0,0,IF(W15=1,1,IF(OR(R15*$F$8=1,S15*$F$9=1,F15>=AF15),2,0))) -> #N/A | AF15: =HLOOKUP(C15,$K$6:$O$7,2,FALSE) -> #N/A
B16: =+B15+1 -> 4 | G16: =IF(ISERROR(AVERAGE(F$13:F16)),"n/a",AVERAGE(F$13:F16)) -> n/a | H16: =G16 -> n/a | O16: =IF(J16=1,"A",IF(K16=1,"B",IF(L16=1,"C",IF(M16=1,"D",IF(N16=1,"E","n/a"))))) -> n/a | V16: =IF(O16="n/a","",IF(O16=U16,1,"")) | W16: =IF(O16="n/a","",IF(O16<>U16,1,"")) | X16: =SUM(V$13:V16)/COUNTA(B$13:B16) -> 0 | AE16: =+IF($F$4=0,0,IF(W16=1,1,IF(OR(R16*$F$8=1,S16*$F$9=1,F16>=AF16),2,0))) -> #N/A | AF16: =HLOOKUP(C16,$K$6:$O$7,2,FALSE) -> #N/A
B17: =+B16+1 -> 5 | G17: =IF(ISERROR(AVERAGE(F$13:F17)),"n/a",AVERAGE(F$13:F17)) -> n/a | H17: =G17 -> n/a | O17: =IF(J17=1,"A",IF(K17=1,"B",IF(L17=1,"C",IF(M17=1,"D",IF(N17=1,"E","n/a"))))) -> n/a | V17: =IF(O17="n/a","",IF(O17=U17,1,"")) | W17: =IF(O17="n/a","",IF(O17<>U17,1,"")) | X17: =SUM(V$13:V17)/COUNTA(B$13:B17) -> 0 | AE17: =+IF($F$4=0,0,IF(W17=1,1,IF(OR(R17*$F$8=1,S17*$F$9=1,F17>=AF17),2,0))) -> #N/A | AF17: =HLOOKUP(C17,$K$6:$O$7,2,FALSE) -> #N/A | AU17: Correct | AV17: Know | AW17: POE | AX17: Guess | AY17: Incorrect | AZ17: Concept | BA17: Stpd Error | BB17: Accuracy | BC17: Timing | BD17: +/- Goal
B18: =+B17+1 -> 6 | G18: =IF(ISERROR(AVERAGE(F$13:F18)),"n/a",AVERAGE(F$13:F18)) -> n/a | H18: =G18 -> n/a | O18: =IF(J18=1,"A",IF(K18=1,"B",IF(L18=1,"C",IF(M18=1,"D",IF(N18=1,"E","n/a"))))) -> n/a | V18: =IF(O18="n/a","",IF(O18=U18,1,"")) | W18: =IF(O18="n/a","",IF(O18<>U18,1,"")) | X18: =SUM(V$13:V18)/COUNTA(B$13:B18) -> 0 | AE18: =+IF($F$4=0,0,IF(W18=1,1,IF(OR(R18*$F$8=1,S18*$F$9=1,F18>=AF18),2,0))) -> #N/A | AF18: =HLOOKUP(C18,$K$6:$O$7,2,FALSE) -> #N/A | AR18: All Questions | AU18: =V1015 -> 0 | AV18: =Q1015 -> 0 | AW18: =R1015 -> 0 | AX18: =S1015 -> 0 | AY18: =W1015 -> 0 | AZ18: =Z1015 -> 0 | BA18: =AA1015 -> 0 | BB18: =IF(ISERROR(AU18/(AU18+AY18)),"n/a",AU18/(AU18+AY18)) -> n/a | BC18: =IF(ISERROR(TEXT($E$1023,"00")&":"&TEXT($F$1023,"00")),"n/a",TEXT($E$1023,"00")&":"&TEXT($F$1023,"00")) -> n/a | BD18: =IF(ISERROR(BF18&TEXT($E$1040,"00")&":"&TEXT($F$1040,"00")),"n/a",BF18&TEXT($E$1040,"00")&":"&TEXT($F$1040,"00")) -> n/a | BF18: =IF(F1032<0,"-","+") -> #VALUE!
B19: =+B18+1 -> 7 | G19: =IF(ISERROR(AVERAGE(F$13:F19)),"n/a",AVERAGE(F$13:F19)) -> n/a | H19: =G19 -> n/a | O19: =IF(J19=1,"A",IF(K19=1,"B",IF(L19=1,"C",IF(M19=1,"D",IF(N19=1,"E","n/a"))))) -> n/a | V19: =IF(O19="n/a","",IF(O19=U19,1,"")) | W19: =IF(O19="n/a","",IF(O19<>U19,1,"")) | X19: =SUM(V$13:V19)/COUNTA(B$13:B19) -> 0 | AE19: =+IF($F$4=0,0,IF(W19=1,1,IF(OR(R19*$F$8=1,S19*$F$9=1,F19>=AF19),2,0))) -> #N/A | AF19: =HLOOKUP(C19,$K$6:$O$7,2,FALSE) -> #N/A | AV19: =+IF(ISERROR(AV18/SUM($AU$18,$AY$18)),"n/a",AV18/SUM($AU$18,$AY$18)) -> n/a | AW19: =+IF(ISERROR(AW18/SUM($AU$18,$AY$18)),"n/a",AW18/SUM($AU$18,$AY$18)) -> n/a | AX19: =+IF(ISERROR(AX18/SUM($AU$18,$AY$18)),"n/a",AX18/SUM($AU$18,$AY$18)) -> n/a | AZ19: =+IF(ISERROR(AZ18/$AY$18),"n/a",AZ18/$AY$18) -> n/a | BA19: =+IF(ISERROR(BA18/$AY$18),"n/a",BA18/$AY$18) -> n/a
B20: =+B19+1 -> 8 | G20: =IF(ISERROR(AVERAGE(F$13:F20)),"n/a",AVERAGE(F$13:F20)) -> n/a | H20: =G20 -> n/a | O20: =IF(J20=1,"A",IF(K20=1,"B",IF(L20=1,"C",IF(M20=1,"D",IF(N20=1,"E","n/a"))))) -> n/a | V20: =IF(O20="n/a","",IF(O20=U20,1,"")) | W20: =IF(O20="n/a","",IF(O20<>U20,1,"")) | X20: =SUM(V$13:V20)/COUNTA(B$13:B20) -> 0 | AE20: =+IF($F$4=0,0,IF(W20=1,1,IF(OR(R20*$F$8=1,S20*$F$9=1,F20>=AF20),2,0))) -> #N/A | AF20: =HLOOKUP(C20,$K$6:$O$7,2,FALSE) -> #N/A | AR20: Performance by Question Type
B21: =+B20+1 -> 9 | G21: =IF(ISERROR(AVERAGE(F$13:F21)),"n/a",AVERAGE(F$13:F21)) -> n/a | H21: =G21 -> n/a | O21: =IF(J21=1,"A",IF(K21=1,"B",IF(L21=1,"C",IF(M21=1,"D",IF(N21=1,"E","n/a"))))) -> n/a | V21: =IF(O21="n/a","",IF(O21=U21,1,"")) | W21: =IF(O21="n/a","",IF(O21<>U21,1,"")) | X21: =SUM(V$13:V21)/COUNTA(B$13:B21) -> 0 | AE21: =+IF($F$4=0,0,IF(W21=1,1,IF(OR(R21*$F$8=1,S21*$F$9=1,F21>=AF21),2,0))) -> #N/A | AF21: =HLOOKUP(C21,$K$6:$O$7,2,FALSE) -> #N/A
B22: =+B21+1 -> 10 | G22: =IF(ISERROR(AVERAGE(F$13:F22)),"n/a",AVERAGE(F$13:F22)) -> n/a | H22: =G22 -> n/a | O22: =IF(J22=1,"A",IF(K22=1,"B",IF(L22=1,"C",IF(M22=1,"D",IF(N22=1,"E","n/a"))))) -> n/a | V22: =IF(O22="n/a","",IF(O22=U22,1,"")) | W22: =IF(O22="n/a","",IF(O22<>U22,1,"")) | X22: =SUM(V$13:V22)/COUNTA(B$13:B22) -> 0 | AE22: =+IF($F$4=0,0,IF(W22=1,1,IF(OR(R22*$F$8=1,S22*$F$9=1,F22>=AF22),2,0))) -> #N/A | AF22: =HLOOKUP(C22,$K$6:$O$7,2,FALSE) -> #N/A | AR22: Problem Solving | AU22: =V1017 -> 0 | AV22: =Q1017 -> 0 | AW22: =R1017 -> 0 | AX22: =S1017 -> 0 | AY22: =$W$1017 -> 0 | AZ22: =Z1017 -> 0 | BA22: =AA1017 -> 0 | BB22: =IF(ISERROR(AU22/(AU22+AY22)),"n/a",AU22/(AU22+AY22)) -> n/a | BC22: =IF(ISERROR(TEXT($E$1025,"00")&":"&TEXT($F$1025,"00")),"n/a",TEXT($E$1025,"00")&":"&TEXT($F$1025,"00")) -> n/a | BD22: =IF(ISERROR(BF22&TEXT($E$1042,"00")&":"&TEXT($F$1042,"00")),"n/a",BF22&TEXT($E$1042,"00")&":"&TEXT($F$1042,"00")) -> n/a | BF22: =IF(F1034<0,"-","+") -> #VALUE!
B23: =+B22+1 -> 11 | G23: =IF(ISERROR(AVERAGE(F$13:F23)),"n/a",AVERAGE(F$13:F23)) -> n/a | H23: =G23 -> n/a | O23: =IF(J23=1,"A",IF(K23=1,"B",IF(L23=1,"C",IF(M23=1,"D",IF(N23=1,"E","n/a"))))) -> n/a | V23: =IF(O23="n/a","",IF(O23=U23,1,"")) | W23: =IF(O23="n/a","",IF(O23<>U23,1,"")) | X23: =SUM(V$13:V23)/COUNTA(B$13:B23) -> 0 | AE23: =+IF($F$4=0,0,IF(W23=1,1,IF(OR(R23*$F$8=1,S23*$F$9=1,F23>=AF23),2,0))) -> #N/A | AF23: =HLOOKUP(C23,$K$6:$O$7,2,FALSE) -> #N/A | AV23: =+IF(ISERROR(AV22/SUM($AU$22,$AY$22)),"n/a",AV22/SUM($AU$22,$AY$22)) -> n/a | AW23: =+IF(ISERROR(AW22/SUM($AU$22,$AY$22)),"n/a",AW22/SUM($AU$22,$AY$22)) -> n/a | AX23: =+IF(ISERROR(AX22/SUM($AU$22,$AY$22)),"n/a",AX22/SUM($AU$22,$AY$22)) -> n/a | AZ23: =+IF(ISERROR(AZ22/$AY$22),"n/a",AZ22/$AY$22) -> n/a | BA23: =+IF(ISERROR(BA22/$AY$22),"n/a",BA22/$AY$22) -> n/a
B24: =+B23+1 -> 12 | G24: =IF(ISERROR(AVERAGE(F$13:F24)),"n/a",AVERAGE(F$13:F24)) -> n/a | H24: =G24 -> n/a | O24: =IF(J24=1,"A",IF(K24=1,"B",IF(L24=1,"C",IF(M24=1,"D",IF(N24=1,"E","n/a"))))) -> n/a | V24: =IF(O24="n/a","",IF(O24=U24,1,"")) | W24: =IF(O24="n/a","",IF(O24<>U24,1,"")) | X24: =SUM(V$13:V24)/COUNTA(B$13:B24) -> 0 | AE24: =+IF($F$4=0,0,IF(W24=1,1,IF(OR(R24*$F$8=1,S24*$F$9=1,F24>=AF24),2,0))) -> #N/A | AF24: =HLOOKUP(C24,$K$6:$O$7,2,FALSE) -> #N/A
B25: =+B24+1 -> 13 | G25: =IF(ISERROR(AVERAGE(F$13:F25)),"n/a",AVERAGE(F$13:F25)) -> n/a | H25: =G25 -> n/a | O25: =IF(J25=1,"A",IF(K25=1,"B",IF(L25=1,"C",IF(M25=1,"D",IF(N25=1,"E","n/a"))))) -> n/a | V25: =IF(O25="n/a","",IF(O25=U25,1,"")) | W25: =IF(O25="n/a","",IF(O25<>U25,1,"")) | X25: =SUM(V$13:V25)/COUNTA(B$13:B25) -> 0 | AE25: =+IF($F$4=0,0,IF(W25=1,1,IF(OR(R25*$F$8=1,S25*$F$9=1,F25>=AF25),2,0))) -> #N/A | AF25: =HLOOKUP(C25,$K$6:$O$7,2,FALSE) -> #N/A | AR25: Data Sufficiency | AU25: =$V$1018 -> 0 | AV25: =Q1018 -> 0 | AW25: =R1018 -> 0 | AX25: =S1018 -> 0 | AY25: =$W$1018 -> 0 | AZ25: =Z1018 -> 0 | BA25: =AA1018 -> 0 | BB25: =IF(ISERROR(AU25/(AU25+AY25)),"n/a",AU25/(AU25+AY25)) -> n/a | BC25: =IF(ISERROR(TEXT($E$1026,"00")&":"&TEXT($F$1026,"00")),"n/a",TEXT($E$1026,"00")&":"&TEXT($F$1026,"00")) -> n/a | BD25: =IF(ISERROR(BF25&TEXT($E$1043,"00")&":"&TEXT($F$1043,"00")),"n/a",BF25&TEXT($E$1043,"00")&":"&TEXT($F$1043,"00")) -> n/a | BF25: =IF(F1035<0,"-","+") -> #VALUE!
B26: =+B25+1 -> 14 | G26: =IF(ISERROR(AVERAGE(F$13:F26)),"n/a",AVERAGE(F$13:F26)) -> n/a | H26: =G26 -> n/a | O26: =IF(J26=1,"A",IF(K26=1,"B",IF(L26=1,"C",IF(M26=1,"D",IF(N26=1,"E","n/a"))))) -> n/a | V26: =IF(O26="n/a","",IF(O26=U26,1,"")) | W26: =IF(O26="n/a","",IF(O26<>U26,1,"")) | X26: =SUM(V$13:V26)/COUNTA(B$13:B26) -> 0 | AE26: =+IF($F$4=0,0,IF(W26=1,1,IF(OR(R26*$F$8=1,S26*$F$9=1,F26>=AF26),2,0))) -> #N/A | AF26: =HLOOKUP(C26,$K$6:$O$7,2,FALSE) -> #N/A | AV26: =+IF(ISERROR(AV25/SUM($AU$25,$AY$25)),"n/a",AV25/SUM($AU$25,$AY$25)) -> n/a | AW26: =+IF(ISERROR(AW25/SUM($AU$25,$AY$25)),"n/a",AW25/SUM($AU$25,$AY$25)) -> n/a | AX26: =+IF(ISERROR(AX25/SUM($AU$25,$AY$25)),"n/a",AX25/SUM($AU$25,$AY$25)) -> n/a | AZ26: =+IF(ISERROR(AZ25/$AY$25),"n/a",AZ25/$AY$25) -> n/a | BA26: =+IF(ISERROR(BA25/$AY$25),"n/a",BA25/$AY$25) -> n/a
